Workbook

Sheet Summary Dashboard
A1: INDICATORS | B1: ACTIVITIES | C1: TARGET | D1: ACHIEVED | E1: VARIANCE | F1: PERCENTAGE ACHIEVED
A2: RESULT 2:Local partners effectively respond to GBV and protection risks among new arrivals appropriate to their age, gender, and disability.
A3: Indicator 1 Number of survivors who receive an appropriate response to GBV | B3: GBV Case Management | C3: 550 | D3: =SUM('Activity Tracking Table'!KG4+'Activity Tracking Table'!KG5) -> 467 | E3: ='Summary Dashboard'!C3-'Summary Dashboard'!D3 -> 83 | F3: =D3/C3 -> 0.84909091 | G3: =(F5+F3)/2 -> 0.92454545
B4: Provide in kind material support to GBV survivors (dignity kits) -(through referrals) | C4: 300 | D4: 64 | E4: =C4-D4 -> 236 | F4: =D4/C4 -> 0.21333333
B5: GBV Case Conferencing | C5: 2 | D5: 2 | E5: =C5-D5 -> 0 | F5: =D5/C5 -> 1
A6: Indicator 2 Number of participants showing an increased knowledge on the protection subject in focus | B6: Training GBV Community Structures | C6: 130 | D6: ='Activity Tracking Table'!KG10 -> 97 | E6: =C6-D6 -> 33 | F6: =D6/C6 -> 0.74615385 | G6: =F6 -> 0.74615385
B7: Clinical Health Training for 30 health workers, clinical care sexual assault. 30 police officers | C7: 60 | D7: ='Activity Tracking Table'!KG11 -> 0 | E7: =C7-D7 -> 60 | F7: =D7/C7 -> 0
A8: Indicator 3 Number of persons effectively referred to other specialised service or assistance providers | B8: GBV Referrals | C8: 550 | D8: ='Activity Tracking Table'!#REF! -> #REF! | E8: =C8-D8 -> #REF! | F8: =D8/C8 -> #REF! | G8: =F8 -> #REF!
A9: Indicator 4 Number of persons with increased/appropriate information on relevant rights and/or entitlements | B9: Training WGSS CMCS on leadership and safe space management and income generating activities [IGA] | C9: 25 | D9: ='Activity Tracking Table'!KG12 -> 48 | E9: =C9-D9 -> -23 | F9: =D9/C9 -> 1.92 | G9: =(F9+F11)/2 -> 1.46
B10: Training Facilitators for Women and Girls Safe Spaces | C10: 2 | D10: ='Activity Tracking Table'!KG13 -> 0 | E10: =C10-D10 -> 2 | F10: =D10/C10 -> 0
B11: Provide working Tools to GBV Structures | C11: 50 | D11: ='Activity Tracking Table'!KG14 -> 50 | E11: =C11-D11 -> 0 | F11: =D11/C11 -> 1
B12: Sensitization dialogues & Awarenes Sessions | D12: ='Activity Tracking Table'!KG22+'Activity Tracking Table'!KG23+'Activity Tracking Table'!KG24 -> 13550
A13: Indicator 5 Percentage of women and girls with specific protection needs (e.g., survivors of gender-based violence, persons with disabilities, pregnant or lactating women) who report feeling safe and supported after accessing services at the women and girls safe spaces. | B13: Provide integrated services to women and girls at the safe spaces | C13: 4500 | D13: ='Activity Tracking Table'!#REF! -> #REF! | E13: =C13-D13 -> #REF! | F13: =D13/C13 -> #REF! | G13: =(F13+F16+F17)/3 -> #REF!
B15: Referrals made from Women and Girls Safe Spaces | C15: 45 | D15: ='Activity Tracking Table'!KG16 -> 22 | E15: =C15-D15 -> 23 | F15: =D15/C15 -> 0.48888889
B16: Establish or Maintain Girl's Safe Spaces | C16: 3 | D16: 2 | E16: =C16-D16 -> 1 | F16: =D16/C16 -> 0.66666667
B17: Comic Books Sessions | C17: 450 | D17: ='Activity Tracking Table'!KG35 -> 275 | E17: =C17-D17 -> 175 | F17: =D17/C17 -> 0.61111111
B18: Skilling to girls | C18: 225 | D18: ='Activity Tracking Table'!KG17 -> 0 | E18: =C18-D18 -> 225 | F18: =D18/C18 -> 0
A20: RESULT 3:Local partners effectively respond to Child Protection risks among new arrivals appropriate to their age, gender, and disability
A21: Indicator 1: Number of persons who receive an appropriate response | B21: Case Management (Children) Nakivale | C21: 1350 | D21: ='Activity Tracking Table'!KG34 -> 429 | E21: =C21-D21 -> 921 | F21: =D21/C21 -> 0.31777778 | G21: =(F21+F22+F25+F26+F31+F30)/6 -> 0.9425463
B22: Case Management (Children) Nyakabande | C22: 2000 | D22: ='Activity Tracking Table'!KG35 -> 275 | E22: =C22-D22 -> 1725 | F22: =D22/C22 -> 0.1375
B23: Identify register, assess and support children to access different services through the referral pathway (Nakivale) | C23: 1200 | D23: ='Activity Tracking Table'!KG36 -> 1000 | E23: =C23-D23 -> 200 | F23: =D23/C23 -> 0.83333333
B24: Identify register, assess and support children to access different services through the referral pathway (Nyakabande) | C24: 200 | D24: ='Activity Tracking Table'!KG37 -> 134 | E24: =C24-D24 -> 66 | F24: =D24/C24 -> 0.67
B25: Case Conferencing | C25: 5 | D25: ='Activity Tracking Table'!KG38 -> 6 | E25: =C25-D25 -> -1 | F25: =D25/C25 -> 1.2
B26: Team UP | C26: 240 | D26: ='Activity Tracking Table'!KG39 -> 240 | E26: =C26-D26 -> 0 | F26: =D26/C26 -> 1
B27: Training Team Up facilitators | D27: ='Activity Tracking Table'!KG55 -> 9 | E27: ='Activity Tracking Table'!BG319 -> 0
B28: Facilitate CFS Facilitators to support activities at the CFS centers | C28: 6 | D28: 7 | E28: =C28-D28 -> -1 | F28: =D28/C28 -> 1.1666667
B29: Provide material support to foster parents and care givers | C29: 50 | D29: ='Activity Tracking Table'!KG41 -> 69 | E29: =C29-D29 -> -19 | F29: =D29/C29 -> 1.38
B30: Support to lactating mothers | C30: 50 | D30: ='Activity Tracking Table'!KG42 -> 100 | E30: =C30-D30 -> -50 | F30: =D30/C30 -> 2
B31: Provide Individual Protection Assistance to children like blankets, sleeping mats, clothes.etc | C31: 600 | D31: ='Activity Tracking Table'!KG43 -> 600 | E31: =C31-D31 -> 0 | F31: =D31/C31 -> 1
A32: Indicator 2: Number of unaccompanied and/or separated children who are reunited with their caregivers OR in appropriate protective arrangements based on BIA. | B32: Conduct child family tracing and reunification | C32: 10 | D32: ='Activity Tracking Table'!KG47 -> 70 | E32: =C32-D32 -> -60 | F32: =D32/C32 -> 7
B33: Unaccompanied & seperated Children supported | D33: ='Activity Tracking Table'!KG48 -> 135
B34: Foster parents identified | C34: 100 | D34: ='Activity Tracking Table'!KG49 -> 30 | E34: =C34-D34 -> 70
B35: Children placed under foster care | D35: ='Activity Tracking Table'!KG50 -> 48
A36: Indicator 3: Number of participants showing an increased knowledge on the protection subject in focus. | B36: Training and mentorship of community-level actors and structures Support to parasocial workers, shelter leaders, community leaders. (Strengthening the capacity of community structures) | C36: 150 | D36: ='Activity Tracking Table'!KG51 -> 150 | E36: =C36-D36 -> 0 | F36: =D36/C36 -> 1
A37: Indicator 4: Number of parents, caregivers, foster families, and community stakeholders who receive training, guidance and support to address child protection concerns | B37: Positive Parenting and Parenting without violence approaches (Nakivale & Nyakabande) | C37: 350 | D37: ='Activity Tracking Table'!KG62 -> 866 | E37: =C37-D37 -> -516 | F37: =(D38+D37)/1350 -> 1.322963 | H37: New Target for both activities is 1350 👈Achieved Percentage is for both Activities in comparison with new target.
B38: Sensitize parents, caregivers, and community members on the prevention of abuse and neglect of children (Nakivale & Nyakabande) | C38: 960 | D38: ='Activity Tracking Table'!KG63 -> 920 | E38: =C38-D38 -> 40 | F38: =D38/C38 -> 0.95833333
B39: Train CPCs, Parasocial workers, shelter leaders and community leaders. | C39: 5 | D39: ='Activity Tracking Table'!KG54 -> 0 | E39: =C39-D39 -> 5 | F39: =D39/C39 -> 0
B40: Training and mentoring for district local government staff (Nakivale and Nyakabande) | C40: 120 | D40: ='Activity Tracking Table'!KG53 -> 0 | E40: =C40-D40 -> 120 | F40: =D40/C40 -> 0
B41: Facilitation for Follow-up through home visits for children at high protection risks (To be conducted by the LG, in coordination with the CPCs to follow-up on the safety of these children. SubCounty and District specific CPCs will be supported to meet regularly through this action.) | C41: 4 | D41: ='Activity Tracking Table'!KG65 -> 15 | E41: =C41-D41 -> -11 | F41: =D41/C41 -> 3.75
B42: Traning CPS and Shelter leaders (5 CPCs and 5 Shelter Leaders) | C42: 10 | D42: ='Activity Tracking Table'!#REF! -> #REF! | E42: =C42-D42 -> #REF! | F42: =D42/C42 -> #REF!
...

Sheet Activity Tracking Table
A1: STEPS - Sustainable Transition to Locally Led Emergency Protection Services | C1: Location | D1: Target | E1: 45474 | K1: Jul Totals | O1: 45505 | U1: Aug Totals | Y1: 45536 | AE1: Sep Totals | AI1: 45566 | AO1: Oct Totals | AT1: Quarter 1 Totals | AW1: Quarter 1 | AZ1: Total Female Refugees | BA1: Total Male Refugees | BB1: Total Female Host | BC1: Total Male Host | BD1: 45597 | BJ1: Nov Totals | BN1: 45627 | BT1: Dec Totals | CC1: 45658 | CI1: Jan Totals | CM1: 45689 | CS1: Feb Totals | CW1: Quarter 2 | DA1: Quarter 2 | DD1: Total Female Refugees | DE1: Total Male Refugees | DF1: Total Female Host | DG1: Total Male Host | DH1: Total Achievement Year 1 | DI1: 45717 | DO1: Mar Totals | DS1: 45748 | DY1: Apr Totals | EC1: 45778 | EI1: May Totals | EM1: 45809 | ES1: Jun Totals | EW1: Quarter 3 | FA1: Quarter 3 | FD1: Total Female Refugees | FE1: Total Male Refugees | FF1: Total Female Host | FG1: Total Male Host | FH1: Total Female Jan-Jun | FI1: Total Male Jan-Jun | FJ1: Total | FN1: 45839 | FT1: Jul Totals | FX1: 45870 | GD1: Aug Totals | GH1: 45901 | GN1: Sep Totals | GR1: Nov 2024- Sep 2025 Totals | GX1: 45931 | HD1: Oct Totals | HH1: Quarter 4 | HN1: Quarter 4 | HQ1: Total Female Refugees | HR1: Total Male Refugees | HS1: Total Female Host | HT1: Total Male Host | HU1: 45962 | IA1: Nov Totals | IE1: 45992 | IK1: Dec Totals | IO1: 46023 | IU1: Jan Totals | IY1: 46054 | JE1: Feb Totals | JI1: Quarter 5 | JM1: Quarter 5 | JP1: 46082 | JV1: Mar Totals | JZ1: Total Year 2 | KA1: Disagregated Totals | KG1: Total Reach
E2: Refugee | H2: National | O2: Refugee | R2: National | Y2: Refugee | AB2: National | AI2: Refugee | AL2: National | BD2: Refugee | BG2: National | BN2: Refugee | BQ2: National | BX2: Total Female Refugees | BY2: Total Male Refugees | BZ2: Total Female Host | CA2: Total Male Host | CB2: Total Achievement Year 1 | CC2: Refugee | CF2: National | CM2: Refugee | CP2: National | DI2: Refugee | DL2: National | DS2: Refugee | DV2: National | EC2: Refugee | EF2: National | EM2: Refugee | EP2: National | FK2: Cumulative Female | FL2: Cumulative Male | FM2: Cumulative Total | FN2: Refugee | FQ2: National | FX2: Refugee | GA2: National | GH2: Refugee | GK2: National | GR2: Total Female | GS2: Total Male | GT2: Total Female Refugees | GU2: Total Male Refugees | GV2: Total Female Host | GW2: Total Male Host | GX2: Refugee | HA2: National | HH2: Total Female Q! | HI2: Total Male Q1 | HJ2: Total Female Refugees | HK2: Total Male Refugees | HL2: Total Female Host | HM2: Total Male Host | HN2: Target | HO2: Achieved | HP2: % Achieved | HU2: Refugee | HX2: National | IE2: Refugee | IH2: National | IO2: Refugee | IR2: National | IY2: Refugee | JB2: National | JP2: Refugee | JS2: National | KA2: Total Female | KB2: Total Male | KC2: Total Female Refugees | KD2: Total Male Refugees | KE2: Total Female Host | KF2: Total Male Host
A3: RESULT 2:Local partners effectively respond to GBV and protection risks among new arrivals appropriate to their age, gender, and disability. | E3: Female | F3: Male | G3: Total | H3: Female | I3: Male | J3: Total | K3: Total Female | L3: Total Male | M3: Total | N3: Sessions | O3: Female | P3: Male | Q3: Total | R3: Female | S3: Male | T3: Total | U3: Total Female | V3: Total Male | W3: Total | X3: Sessions | Y3: Female | Z3: Male | AA3: Total | AB3: Female | AC3: Male | AD3: Total | AE3: Total Female | AF3: Total Male | AG3: Total | AH3: Sessions | AI3: Female | AJ3: Male | AK3: Total | AL3: Female | AM3: Male | AN3: Total | AO3: Total Female | AP3: Total Male | AQ3: Total | AR3: Sessions | AS3: Total Female Q! | AT3: Total Male Q1 | AU3: Total Refugees Q1 | AV3: Total Nationals Q1 | AW3: Target | AX3: Achieved | AY3: % Achieved | BD3: Female | BE3: Male | BF3: Total | BG3: Female | BH3: Male | BI3: Total | BJ3: Total Female | BK3: Total Male | BL3: Total | BM3: Sessions | BN3: Female | BO3: Male | BP3: Total | BQ3: Female | BR3: Male | BS3: Total | BT3: Total Female | BU3: Total Male | BV3: Total | BW3: Sessions | CC3: Female | CD3: Male | CE3: Total | CF3: Female | CG3: Male | CH3: Total | CI3: Total Female | CJ3: Total Male | CK3: Total | CL3: Sessions | CM3: Female | CN3: Male | CO3: Total | CP3: Female | CQ3: Male | CR3: Total | CS3: Total Female | CT3: Total Male | CU3: Total | CV3: Sessions | CW3: Total Female Q2 | CX3: Total Male Q2 | CY3: Total Refugees Q2 | CZ3: Total Nationals Q2 | DA3: Target | DB3: Achieved | DC3: % Achieved | DI3: Female | DJ3: Male | DK3: Total | DL3: Female | DM3: Male | DN3: Total | DO3: Total Female | DP3: Total Male | DQ3: Total | DR3: Sessions | DS3: Female | DT3: Male | DU3: Total | DV3: Female | DW3: Male | DX3: Total | DY3: Total Female | DZ3: Total Male | EA3: Total | EB3: Sessions | EC3: Female | ED3: Male | EE3: Total | EF3: Female | EG3: Male | EH3: Total | EI3: Total Female | EJ3: Total Male | EK3: Total | EL3: Sessions | EM3: Female | EN3: Male | EO3: Total | EP3: Female | EQ3: Male | ER3: Total | ES3: Total Female | ET3: Total Male | EU3: Total | EV3: Sessions | EW3: Total Female Q3 | EX3: Total Male Q3 | EY3: Total Refugees Q3 | EZ3: Total Nationals Q3 | FA3: Target | FB3: Achieved | FC3: % Achieved | FN3: Female | FO3: Male | FP3: Total | FQ3: Female | FR3: Male | FS3: Total | FT3: Total Female | FU3: Total Male | FV3: Total | FW3: Sessions | FX3: Female | FY3: Male | FZ3: Total | GA3: Female | GB3: Male | GC3: Total | GD3: Total Female | GE3: Total Male | GF3: Total | GG3: Sessions | GH3: Female | GI3: Male | GJ3: Total | GK3: Female | GL3: Male | GM3: Total | GN3: Total Female | GO3: Total Male | GP3: Total | GQ3: Sessions | GX3: Female | GY3: Male | GZ3: Total | HA3: Female | HB3: Male | HC3: Total | HD3: Total Female | HE3: Total Male | HF3: Total | HG3: Sessions | HU3: Female | HV3: Male | HW3: Total | HX3: Female | HY3: Male | HZ3: Total | IA3: Total Female | IB3: Total Male | IC3: Total | ID3: Sessions | IE3: Female | IF3: Male | IG3: Total | IH3: Female | II3: Male | IJ3: Total | IK3: Total Female | IL3: Total Male | IM3: Total | IN3: Sessions | IO3: Female | IP3: Male | IQ3: Total | IR3: Female | IS3: Male | IT3: Total | IU3: Total Female | IV3: Total Male | IW3: Total | IX3: Sessions | IY3: Female | IZ3: Male | JA3: Total | JB3: Female | JC3: Male | JD3: Total | JE3: Total Female | JF3: Total Male | JG3: Total | JI3: Total Female Q! | JJ3: Total Male Q1 | JK3: Total Refugees Q1 | JL3: Total Nationals Q1 | JM3: Target | JN3: Achieved | JO3: % Achieved | JP3: Female | JQ3: Male | JR3: Total | JS3: Female | JT3: Male | JU3: Total | JV3: Total Female | JW3: Total Male | JX3: Total | JY3: Sessions | KG3: Total Reach | KH3: Target | KI3: Variance | KJ3: Achieved
A4: Indicator 1 Number of survivors who receive an appropriate response to GBV | B4: GBV Case Management | C4: Nakivale | D4: 550 | O4: 8 | P4: 1 | Q4: =SUM(O4:P4) -> 9 | R4: 0 | S4: 0 | T4: =SUM(R4:S4) -> 0 | U4: =SUM(O4+R4) -> 8 | V4: =SUM(P4+S4) -> 1 | W4: =SUM(U4:V4) -> 9 | Y4: 11 | Z4: 1 | AA4: =SUM(Y4:Z4) -> 12 | AB4: 1 | AC4: 0 | AD4: =SUM(AB4:AC4) -> 1 | AE4: =SUM(Y4+AB4) -> 12 | AF4: =SUM(Z4+AC4) -> 1 | AG4: =SUM(AE4:AF4) -> 13 | AI4: 17 | AJ4: 0 | AK4: =SUM(AI4:AJ4) -> 17 | AL4: 0 | AM4: 0 | AN4: =SUM(AL4:AM4) -> 0 | AO4: =SUM(AI4+AL4) -> 17 | AP4: =SUM(AJ4+AM4) -> 0 | AQ4: =SUM(AO4:AP4) -> 17 | AS4: =AO4+AE4+U4+K4 -> 37 | AT4: =AP4+AF4+V4+L4 -> 2 | AU4: =AK4+AA4+Q4+G4 -> 38 | AV4: =J4+T4+AD4+AN4 -> 1 | AW4: 220 | AX4: =SUM(AQ4+AG4+W4+M4) -> 39 | AY4: =AX4/AW4 -> 0.17727273 | AZ4: =SUM(E4+O4+Y4+AI4) -> 36 | BA4: =F4+P4+Z4+AJ4 -> 2 | BB4: =H4+R4+AB4+AL4 -> 1 | BC4: =I4+S4+AC4+AM4 -> 0 | BD4: 19 | BE4: 0 | BF4: =SUM(BD4:BE4) -> 19 | BG4: 1 | BH4: 0 | BI4: =SUM(BG4:BH4) -> 1 | BJ4: =SUM(BD4+BG4) -> 20 | BK4: =SUM(BE4+BH4) -> 0 | BL4: =SUM(BJ4:BK4) -> 20 | BN4: 9 | BO4: 0 | BP4: =SUM(BN4:BO4) -> 9 | BQ4: 0 | BR4: 0 | BS4: =SUM(BQ4:BR4) -> 0 | BT4: =SUM(BN4+BQ4) -> 9 | BU4: =SUM(BO4+BR4) -> 0 | BV4: =SUM(BT4:BU4) -> 9 | BX4: =BN4+BD4+AI4+Y4+O4+E4 -> 64 | BY4: =BO4+BE4+AJ4+Z4+P4+F4 -> 2 | BZ4: =BQ4+BG4+AL4+AB4+R4+H4 -> 2 | CA4: =BR4+BH4+AM4+AC4+S4+I4 -> 0 | CB4: =BX4+BY4+BZ4+CA4 -> 68 | CC4: 11 | CD4: 0 | CE4: =SUM(CC4:CD4) -> 11 | CF4: 0 | CG4: 0 | CH4: =SUM(CF4:CG4) -> 0 | CI4: =SUM(CC4+CF4) -> 11 | CJ4: =SUM(CD4+CG4) -> 0 | CK4: =SUM(CI4:CJ4) -> 11 | CM4: 18 | CN4: 0 | CO4: =SUM(CM4:CN4) -> 18 | CP4: 0 | CQ4: 0 | CR4: =SUM(CP4:CQ4) -> 0 | CS4: 18 | CT4: =SUM(CN4+CQ4) -> 0 | CU4: =SUM(CS4:CT4) -> 18 | CW4: =SUM(CS4+CI4+BT4+BJ4) -> 58 | CX4: =SUM(CT4+CJ4+BU4+BK4) -> 0 | CY4: =SUM(CU4+CK4+BV4+BL4) -> 58 | CZ4: =SUM(CR4+CH4+BS4+BI4) -> 1 | DA4: 220 | DB4: =SUM(CW4:CX4) -> 58 | DC4: =DB4/DA4 -> 0.26363636 | DD4: =BD4+BN4+CC4+CM4 -> 57 | DE4: =BE4+BO4+CD4+CN4 -> 0 | DF4: =BG4+BQ4+CF4+CP4 -> 1 | DG4: =BH4+BR4+CG4+CQ4 -> 0 | DH4: =DB4+AX4 -> 97 | DI4: 20 | DJ4: 0 | DK4: =SUM(DI4:DJ4) -> 20 | DL4: 0 | DM4: 0 | DN4: =SUM(DL4:DM4) -> 0 | DO4: =SUM(DI4+DL4) -> 20 | DP4: 0 | DQ4: =SUM(DO4:DP4) -> 20 | DS4: 24 | DT4: 0 | DU4: =SUM(DS4:DT4) -> 24 | DV4: 0 | DW4: 0 | DX4: =SUM(DV4:DX4) -> 0 | DY4: =SUM(DS4+DV4) -> 24 | DZ4: =SUM(DT4+DW4) -> 0 | EA4: =SUM(DY4:DZ4) -> 24 | EC4: 14 | ED4: 0 | EE4: =SUM(EC4:ED4) -> 14 | EF4: 0 | EG4: 0 | EH4: =SUM(EF4:EG4) -> 0 | EI4: 14 | EJ4: =SUM(ED4+EG4) -> 0 | EK4: =SUM(EI4:EJ4) -> 14 | EM4: 17 | EN4: 0 | EO4: =SUM(EM4:EN4) -> 17 | EP4: 0 | EQ4: 0 | ER4: =SUM(EP4:EQ4) -> 0 | ES4: =SUM(EM4+EP4) -> 17 | ET4: =SUM(EN4+EQ4) -> 0 | EU4: =SUM(ES4:ET4) -> 17 | EW4: =SUM(ES4+EI4+DY4+DO4) -> 75 | EX4: =SUM(ET4+EJ4+DZ4+DP4) -> 0 | EY4: =SUM(EO4+EE4+DU4+DK4) -> 75 | EZ4: =SUM(ER4+EH4+DX4+DN4) -> 0 | FA4: 75 | FB4: =SUM(EW4:EX4) -> 75 | FC4: =FB4/FA4 -> 1 | FD4: =DI4+DS4+EC4+EM4+CM4+CC4 -> 104 | FE4: =DJ4+DT4+ED4+EN4+CD4+CN4 -> 0 | FF4: =DL4+DV4+EF4+EP4+CP4+CF4 -> 0 | FG4: =DM4+DW4+EG4+EQ4+CG4+CQ4 -> 0 | FH4: =FD4+FF4 -> 104 | FI4: =FE4+FG4 -> 0 | FJ4: =FH4+FI4 -> 104 | FK4: =EW4+CW4+AS4 -> 170 | FL4: =EX4+CX4+AT4 -> 2 | FM4: =FK4+FL4 -> 172 | FN4: 15 | FO4: 0 | FP4: =SUM(FN4:FO4) -> 15 | FQ4: 0 | FR4: 0 | FS4: =SUM(FQ4:FR4) -> 0 | FT4: =FN4+FQ4 -> 15 | FU4: =FO4+FR4 -> 0 | FV4: =SUM(FT4:FU4) -> 15 | FX4: 31 | FY4: 0 | FZ4: =SUM(FX4:FY4) -> 31 | GA4: 0 | GB4: 0 | GC4: =SUM(GA4:GB4) -> 0 | GD4: =FX4+GA4 -> 31 | GE4: =FY4+GB4 -> 0 | GF4: =GD4+GE4 -> 31 | GH4: 21 | GI4: 0 | GJ4: =SUM(GH4:GI4) -> 21 | GK4: 0 | GL4: 0 | GM4: =SUM(GK4:GL4) -> 0 | GN4: =GH4+GK4 -> 21 | GO4: =GI4+GL4 -> 0 | GP4: =GN4+GO4 -> 21 | GR4: =GN4+GD4+FT4+ES4+EI4+DY4+DO4+CS4+CI4+BT4+BJ4 -> 200 | GS4: =GO4+GE4+FU4+ET4+EJ4+DZ4+DP4+CT4+CJ4+BU4+BK4 -> 0 | GT4: =GH4+FX4+FN4+EM4+EC4+DS4+DI4+CM4+CC4+BN4+BD4 -> 199 | GU4: =GI4+FY4+FO4+EN4+ED4+DT4+DJ4+CN4+CD4+BO4+BE4 -> 0 | GV4: =GK4+GA4+FQ4+EP4+EF4+DV4+DL4+CP4+CF4+BQ4+BG4 -> 1 | GW4: =GL4+GB4+FR4+EQ4+EG4+DW4+DM4+CQ4+CG4+BR4+BH4 -> 0 | GX4: 16 | GY4: 0 | GZ4: =GX4+GY4 -> 16 | HA4: 0 | HB4: 0 | HC4: =HA4+HB4 -> 0 | HD4: =GX4+HA4 -> 16 | HE4: =GY4+HB4 -> 0 | HF4: =HD4+HE4 -> 16 | HH4: =HD4+GN4+GD4+FT4 -> 83 | HI4: =GO4+GE4+FU4+HE4 -> 0 | HJ4: =GX4+GH4+FX4+FN4 -> 83 | HK4: =GI4+FY4+GY4+FO4 -> 0 | HL4: =GK4+GA4+FQ4+HA4 -> 0 | HM4: =GL4+HB4+GB4+FR4 -> 0 | HO4: =HF4+GP4+GF4+FV4 -> 83 | HP4: =HO4/HN4 -> #DIV/0! | HQ4: =FN4+FX4+GH4+GX4 -> 83 | HR4: =FO4+FY4+GI4+GY4 -> 0 | HS4: =FQ4+GA4+GK4+HA4 -> 0 | HT4: =FR4+GB4+GL4+HB4 -> 0 | HU4: 11 | HV4: 0 | HW4: =HU4+HV4 -> 11 | HX4: 1 | HY4: 0 | HZ4: =HX4+HY4 -> 1 | IA4: =HU4+HX4 -> 12 | IB4: =HV4+HY4 -> 0 | IC4: =IA4+IB4 -> 12 | JN4: =JG4+IW4+IM4+IC4 -> 12 | JO4: =JN4/JM4 -> #DIV/0! | JZ4: =JX4+JN4+HO4+FB4 -> 170 | KA4: =SUM(JV4+JE4+IU4+IK4+IA4+HD4+GN4+GD4+FT4+ES4+EI4+DY4+DO4+CS4+CI4+BT4+BJ4+AO4+AE4+U4+K4) -> 265 | KB4: =SUM(JW4+JF4+IV4+IL4+IB4+HE4+GO4+GE4+FU4+ET4+EJ4+DZ4+DP4+CT4+CJ4+BU4+BK4+AP4+AF4+V4+L4) -> 2 | KC4: =SUM(JP4+IY4+IO4+IE4+HU4+GX4+GH4+FX4+FN4+EM4+EC4+DS4+DI4+CM4+CC4+BN4+BD4+AI4+Y4+O4+E4) -> 262 | KD4: =SUM(JQ4+IZ4+IP4+IF4+HV4+GY4+GI4+FY4+FO4+EN4+ED4+DT4+DJ4+CN4+CD4+BO4+BE4+AJ4+Z4+P4+F4) -> 2 | KE4: =SUM(JS4+JB4+IR4+IH4+HX4+HA4+GK4+GA4+FQ4+EP4+EF4+DV4+DL4+CP4+CF4+BQ4+BG4+AL4+AB4+R4+H4) -> 3 | KF4: =SUM(JT4+JC4+IS4+II4+HY4+HB4+GL4+GB4+FR4+EQ4+EG4+DW4+DM4+CQ4+CG4+BR4+BH4+AM4+AC4+S4+I4) -> 0 | KG4: =SUM(KA4:KB4) -> 267 | KH4: 550 | KI4: =KH4-(KG4+KG5) -> 83 | KJ4: =(KG4+KG5)/KH4 -> 0.84909091 | KK4: =KG4+KG5 -> 467
B5: GBV Case Management | C5: Nyakabande | AS5: =AO5+AE5+U5+K5 -> 0 | AT5: =AP5+AF5+V5+L5 -> 0 | AU5: =AK5+AA5+Q5+G5 -> 0 | AV5: =AN5 -> 0 | AX5: =SUM(AQ5+AG5+W5+M5) -> 0 | AZ5: =SUM(E5+O5+Y5+AI5) -> 0 | BA5: =F5+P5+Z5+AJ5 -> 0 | BB5: =H5+R5+AB5+AL5 -> 0 | BC5: =I5+S5+AC5+AM5 -> 0 | BX5: =BN5+BD5+AI5+Y5+O5+E5 -> 0 | BY5: =BO5+BE5+AJ5+Z5+P5+F5 -> 0 | BZ5: =BQ5+BG5+AL5+AB5+R5+H5 -> 0 | CA5: =BR5+BH5+AM5+AC5+S5+I5 -> 0 | CB5: =BX5+BY5+BZ5+CA5 -> 0 | CM5: 20 | CO5: =SUM(CM5:CN5) -> 20 | CP5: 0 | CQ5: 0 | CR5: 0 | CS5: 20 | CT5: =(CN5+CQ5) -> 0 | CU5: =SUM(CS5:CT5) -> 20 | CW5: =SUM(CS5+CI5+BT5+BJ5) -> 20 | CX5: =SUM(CT5+CJ5+BU5+BK5) -> 0 | CY5: =SUM(CU5+CK5+BV5+BL5) -> 20 | CZ5: =SUM(CR5+CH5+BS5+BI5) -> 0 | DB5: =CU5+CK5 -> 20 | DD5: =BD5+BN5+CC5+CM5 -> 20 | DE5: =BE5+BO5+CD5+CN5 -> 0 | DF5: =BG5+BQ5+CF5+CP5 -> 0 | DG5: =BH5+BR5+CG5+CQ5 -> 0 | DH5: =DB5+AX5 -> 20 | DI5: 54 | DJ5: 0 | DK5: =SUM(DI5:DJ5) -> 54 | DL5: 0 | DM5: 0 | DN5: 0 | DO5: =DI5+DL5 -> 54 | DP5: 0 | DQ5: =SUM(DO5:DP5) -> 54 | DS5: 32 | DT5: 0 | DU5: =SUM(DS5:DT5) -> 32 | DV5: 0 | DW5: 0 | DX5: =SUM(DV5:DW5) -> 0 | DY5: =SUM(DS5+DV5) -> 32 | DZ5: =SUM(DT5+DW5) -> 0 | EA5: =SUM(DY5:DZ5) -> 32 | EC5: 30 | ED5: 1 | EE5: =SUM(EC5:ED5) -> 31 | EF5: 0 | EG5: 0 | EH5: =SUM(EF5:EG5) -> 0 | EI5: 30 | EJ5: =SUM(ED5+EG5) -> 1 | EK5: =SUM(EI5:EJ5) -> 31 | EM5: 17 | EN5: 0 | EO5: =SUM(EM5:EN5) -> 17 | EP5: 0 | EQ5: 0 | ER5: =SUM(EP5:EQ5) -> 0 | ES5: =SUM(EM5+EP5) -> 17 | ET5: =SUM(EN5+EQ5) -> 0 | EU5: =SUM(ES5:ET5) -> 17 | EW5: =SUM(ES5+EI5+DY5+DO5) -> 133 | EX5: =SUM(ET5+EJ5+DZ5+DP5) -> 1 | EY5: =SUM(EO5+EE5+DU5+DK5) -> 134 | EZ5: =SUM(ER5+EH5+DX5+DN5) -> 0 | FB5: =SUM(EW5:EX5) -> 134 | FD5: =DI5+DS5+EC5+EM5+CM5+CC5 -> 153 | FE5: =DJ5+DT5+ED5+EN5+CD5+CN5 -> 1 | FF5: =DL5+DV5+EF5+EP5+CP5+CF5 -> 0 | FG5: =DM5+DW5+EG5+EQ5+CG5+CQ5 -> 0 | FH5: =FD5+FF5 -> 153 | FI5: =FE5+FG5 -> 1 | FJ5: =FH5+FI5 -> 154 | FK5: =EW5+CW5+AS5 -> 153 | FL5: =EX5+CX5+AT5 -> 1 | FM5: =FK5+FL5 -> 154 | FN5: 10 | FO5: 0 | FP5: =SUM(FN5:FO5) -> 10 | FQ5: 0 | FR5: 0 | FS5: =SUM(FQ5:FR5) -> 0 | FT5: =FN5+FQ5 -> 10 | FU5: =FO5+FR5 -> 0 | FV5: =SUM(FT5:FU5) -> 10 | FX5: 7 | FY5: 0 | FZ5: =SUM(FX5:FY5) -> 7 | GA5: 0 | GB5: 0 | GD5: =FX5+GA5 -> 7 | GE5: =FY5+GB5 -> 0 | GF5: =GD5+GE5 -> 7 | GH5: 9 | GI5: 0 | GJ5: =SUM(GH5:GI5) -> 9 | GK5: 0 | GL5: 0 | GM5: =SUM(GK5:GL5) -> 0 | GN5: =GH5+GK5 -> 9 | GO5: =GI5+GL5 -> 0 | GP5: =GN5+GO5 -> 9 | GR5: =GN5+GD5+FT5+ES5+EI5+DY5+DO5+CS5+CI5+BT5+BJ5 -> 179 | GS5: =GO5+GE5+FU5+ET5+EJ5+DZ5+DP5+CT5+CJ5+BU5+BK5 -> 1 | GT5: =GH5+FX5+FN5+EM5+EC5+DS5+DI5+CM5+CC5+BN5+BD5 -> 179 | GU5: =GI5+FY5+FO5+EN5+ED5+DT5+DJ5+CN5+CD5+BO5+BE5 -> 1 | GV5: =GK5+GA5+FQ5+EP5+EF5+DV5+DL5+CP5+CF5+BQ5+BG5 -> 0 | GW5: =GL5+GB5+FR5+EQ5+EG5+DW5+DM5+CQ5+CG5+BR5+BH5 -> 0 | GX5: 6 | GY5: 0 | GZ5: =GX5+GY5 -> 6 | HA5: 0 | HB5: 0 | HC5: =HA5+HB5 -> 0 | HD5: =GX5+HA5 -> 6 | HE5: =GY5+HB5 -> 0 | HF5: =HD5+HE5 -> 6 | HH5: =HD5+GN5+GD5+FT5 -> 32 | HI5: =GO5+GE5+FU5+HE5 -> 0 | HJ5: =GX5+GH5+FX5+FN5 -> 32 | HK5: =GI5+FY5+GY5+FO5 -> 0 | HL5: =GK5+GA5+FQ5+HA5 -> 0 | HM5: =GL5+HB5+GB5+FR5 -> 0 | HO5: =HF5+GP5+GF5+FV5 -> 32 | HQ5: =FN5+FX5+GH5+GX5 -> 32 | HR5: =FO5+FY5+GI5+GY5 -> 0 | HS5: =FQ5+GA5+GK5+HA5 -> 0 | HT5: =FR5+GB5+GL5+HB5 -> 0 | HU5: 14 | HV5: 0 | HW5: =HU5+HV5 -> 14 | HX5: 0 | HY5: 0 | HZ5: =HX5+HY5 -> 0 | IA5: =HU5+HX5 -> 14 | IB5: =HV5+HY5 -> 0 | IC5: =IA5+IB5 -> 14 | JN5: =JG5+IW5+IM5+IC5 -> 14 | JZ5: =JX5+JN5+HO5+FB5 -> 180 | KA5: =SUM(JV5+JE5+IU5+IK5+IA5+HD5+GN5+GD5+FT5+ES5+EI5+DY5+DO5+CS5+CI5+BT5+BJ5+AO5+AE5+U5+K5) -> 199 | KB5: =SUM(JW5+JF5+IV5+IL5+IB5+HE5+GO5+GE5+FU5+ET5+EJ5+DZ5+DP5+CT5+CJ5+BU5+BK5+AP5+AF5+V5+L5) -> 1 | KC5: =SUM(JP5+IY5+IO5+IE5+HU5+GX5+GH5+FX5+FN5+EM5+EC5+DS5+DI5+CM5+CC5+BN5+BD5+AI5+Y5+O5+E5) -> 199 | KD5: =SUM(JQ5+IZ5+IP5+IF5+HV5+GY5+GI5+FY5+FO5+EN5+ED5+DT5+DJ5+CN5+CD5+BO5+BE5+AJ5+Z5+P5+F5) -> 1 | KE5: =SUM(JS5+JB5+IR5+IH5+HX5+HA5+GK5+GA5+FQ5+EP5+EF5+DV5+DL5+CP5+CF5+BQ5+BG5+AL5+AB5+R5+H5) -> 0 | KF5: =SUM(JT5+JC5+IS5+II5+HY5+HB5+GL5+GB5+FR5+EQ5+EG5+DW5+DM5+CQ5+CG5+BR5+BH5+AM5+AC5+S5+I5) -> 0 | KG5: =SUM(KA5:KB5) -> 200 | KK5: =FY326 -> 0 | KL5: =SUM(KH4-KK5) -> 550
B6: Support GBV screening and registration survivors at the reception and transit centres. (Survivors need based assessment support [ case by case]) | C6: Nakivale & Nyakabande | T6: =SUM(R6:S6) -> 0 | U6: =SUM(O6+R6) -> 0 | V6: =SUM(P6+S6) -> 0 | W6: =SUM(U6:V6) -> 0 | AA6: =SUM(Y6:Z6) -> 0 | AD6: =SUM(AB6:AC6) -> 0 | AE6: =SUM(Y6+AB6) -> 0 | AF6: =SUM(Z6+AC6) -> 0 | AG6: =SUM(AE6:AF6) -> 0 | AS6: =AO6+AE6+U6+K6 -> 0 | AT6: =AP6+AF6+V6+L6 -> 0 | AU6: =AK6+AA6+Q6+G6 -> 0 | AV6: =AN6 -> 0 | AX6: =SUM(AQ6+AG6+W6+M6) -> 0 | AY6: =AX6/AW6 -> #DIV/0! | AZ6: =SUM(E6+O6+Y6+AI6) -> 0 | BA6: =F6+P6+Z6+AJ6 -> 0 | BB6: =H6+R6+AB6+AL6 -> 0 | BC6: =I6+S6+AC6+AM6 -> 0 | BF6: =SUM(BD6:BE6) -> 0 | BI6: =SUM(BG6:BH6) -> 0 | BJ6: =SUM(BD6+BG6) -> 0 | BK6: =SUM(BE6+BH6) -> 0 | BL6: =SUM(BJ6:BK6) -> 0 | BX6: =BN6+BD6+AI6+Y6+O6+E6 -> 0 | BY6: =BO6+BE6+AJ6+Z6+P6+F6 -> 0 | BZ6: =BQ6+BG6+AL6+AB6+R6+H6 -> 0 | CA6: =BR6+BH6+AM6+AC6+S6+I6 -> 0 | CB6: =BX6+BY6+BZ6+CA6 -> 0 | CW6: =SUM(CS6+CI6+BT6+BJ6) -> 0 | CX6: =SUM(CT6+CJ6+BU6+BK6) -> 0 | CY6: =SUM(CU6+CK6+BV6+BL6) -> 0 | CZ6: =SUM(CR6+CH6+BS6+BI6) -> 0 | DB6: =SUM(CW6:CX6) -> 0 | DC6: =DB6/DA6 -> #DIV/0! | DD6: =BD6+BN6+CC6+CM6 -> 0 | DE6: =BE6+BO6+CD6+CN6 -> 0 | DF6: =BG6+BQ6+CF6+CP6 -> 0 | DG6: =BH6+BR6+CG6+CQ6 -> 0 | DH6: =DB6+AX6 -> 0 | DU6: =SUM(DS6:DT6) -> 0 | DX6: =SUM(DV6:DW6) -> 0 | DY6: =SUM(DS6+DV6) -> 0 | DZ6: =SUM(DT6+DW6) -> 0 | EA6: =SUM(DY6:DZ6) -> 0 | EW6: =SUM(ES6+EI6+DY6+DO6) -> 0 | EX6: =SUM(ET6+EJ6+DZ6+DP6) -> 0 | EY6: =SUM(EO6+EE6+DU6+DK6) -> 0 | EZ6: =SUM(ER6+EH6+DX6+DN6) -> 0 | FB6: =SUM(EW6:EX6) -> 0 | FD6: =DI6+DS6+EC6+EM6+CM6+CC6 -> 0 | FE6: =DJ6+DT6+ED6+EN6+CD6+CN6 -> 0 | FF6: =DL6+DV6+EF6+EP6+CP6+CF6 -> 0 | FG6: =DM6+DW6+EG6+EQ6+CG6+CQ6 -> 0 | FH6: =FD6+FF6 -> 0 | FI6: =FE6+FG6 -> 0 | FJ6: =FH6+FI6 -> 0 | FK6: =EW6+CW6+AS6 -> 0 | FL6: =EX6+CX6+AT6 -> 0 | FM6: =FK6+FL6 -> 0 | FN6: 0 | FO6: 0 | FP6: =SUM(FN6:FO6) -> 0 | FQ6: 0 | FR6: 0 | FS6: =SUM(FQ6:FR6) -> 0 | FT6: =FN6+FQ6 -> 0 | FU6: =FO6+FR6 -> 0 | FV6: =SUM(FT6:FU6) -> 0 | GD6: =FX6+GA6 -> 0 | GE6: =FY6+GB6 -> 0 | GF6: =GD6+GE6 -> 0 | GN6: =GH6+GK6 -> 0 | GO6: =GI6+GL6 -> 0 | GP6: =GN6+GO6 -> 0 | GR6: =GN6+GD6+FT6+ES6+EI6+DY6+DO6+CS6+CI6+BT6+BJ6 -> 0 | GS6: =GO6+GE6+FU6+ET6+EJ6+DZ6+DP6+CT6+CJ6+BU6+BK6 -> 0 | GT6: =GH6+FX6+FN6+EM6+EC6+DS6+DI6+CM6+CC6+BN6+BD6 -> 0 | GU6: =GI6+FY6+FO6+EN6+ED6+DT6+DJ6+CN6+CD6+BO6+BE6 -> 0 | GV6: =GK6+GA6+FQ6+EP6+EF6+DV6+DL6+CP6+CF6+BQ6+BG6 -> 0 | GW6: =GL6+GB6+FR6+EQ6+EG6+DW6+DM6+CQ6+CG6+BR6+BH6 -> 0 | GZ6: =GX6+GY6 -> 0 | HC6: =HA6+HB6 -> 0 | HD6: =GX6+HA6 -> 0 | HE6: =GY6+HB6 -> 0 | HF6: =HD6+HE6 -> 0 | HH6: =HD6+GN6+GD6+FT6 -> 0 | HI6: =GO6+GE6+FU6+HE6 -> 0 | HJ6: =GX6+GH6+FX6+FN6 -> 0 | HK6: =GI6+FY6+GY6+FO6 -> 0 | HL6: =GK6+GA6+FQ6+HA6 -> 0 | HM6: =GL6+HB6+GB6+FR6 -> 0 | HO6: =HF6+GP6+GF6+FV6 -> 0 | HP6: =HO6/HN6 -> #DIV/0! | HQ6: =FN6+FX6+GH6+GX6 -> 0 | HR6: =FO6+FY6+GI6+GY6 -> 0 | HS6: =FQ6+GA6+GK6+HA6 -> 0 | HT6: =FR6+GB6+GL6+HB6 -> 0 | HW6: =HU6+HV6 -> 0 | HZ6: =HX6+HY6 -> 0 | IA6: =HU6+HX6 -> 0 | IB6: =HV6+HY6 -> 0 | IC6: =IA6+IB6 -> 0 | JN6: =JG6+IW6+IM6+IC6 -> 0 | JO6: =JN6/JM6 -> #DIV/0! | JZ6: =JX6+JN6+HO6+FB6 -> 0 | KA6: =SUM(JV6+JE6+IU6+IK6+IA6+HD6+GN6+GD6+FT6+ES6+EI6+DY6+DO6+CS6+CI6+BT6+BJ6+AO6+AE6+U6+K6) -> 0 | KB6: =SUM(JW6+JF6+IV6+IL6+IB6+HE6+GO6+GE6+FU6+ET6+EJ6+DZ6+DP6+CT6+CJ6+BU6+BK6+AP6+AF6+V6+L6) -> 0 | KC6: =SUM(JP6+IY6+IO6+IE6+HU6+GX6+GH6+FX6+FN6+EM6+EC6+DS6+DI6+CM6+CC6+BN6+BD6+AI6+Y6+O6+E6) -> 0 | KD6: =SUM(JQ6+IZ6+IP6+IF6+HV6+GY6+GI6+FY6+FO6+EN6+ED6+DT6+DJ6+CN6+CD6+BO6+BE6+AJ6+Z6+P6+F6) -> 0 | KE6: =SUM(JS6+JB6+IR6+IH6+HX6+HA6+GK6+GA6+FQ6+EP6+EF6+DV6+DL6+CP6+CF6+BQ6+BG6+AL6+AB6+R6+H6) -> 0 | KF6: =SUM(JT6+JC6+IS6+II6+HY6+HB6+GL6+GB6+FR6+EQ6+EG6+DW6+DM6+CQ6+CG6+BR6+BH6+AM6+AC6+S6+I6) -> 0 | KG6: =SUM(KA6:KB6) -> 0 | KI6: =KH6-KG6 -> 0 | KJ6: =KG6/KH6 -> #DIV/0! | KK6: =KA4+KA5 -> 464
B7: IPA support to GBV survivors | AZ7: =SUM(E7+O7+Y7+AI7) -> 0 | BA7: =F7+P7+Z7+AJ7 -> 0 | BB7: =H7+R7+AB7+AL7 -> 0 | BC7: =I7+S7+AC7+AM7 -> 0 | BX7: =BN7+BD7+AI7+Y7+O7+E7 -> 0 | BY7: =BO7+BE7+AJ7+Z7+P7+F7 -> 0 | BZ7: =BQ7+BG7+AL7+AB7+R7+H7 -> 0 | CA7: =BR7+BH7+AM7+AC7+S7+I7 -> 0 | CB7: =BX7+BY7+BZ7+CA7 -> 0 | DD7: =BD7+BN7+CC7+CM7 -> 0 | DE7: =BE7+BO7+CD7+CN7 -> 0 | DF7: =BG7+BQ7+CF7+CP7 -> 0 | DG7: =BH7+BR7+CG7+CQ7 -> 0 | DH7: =DB7+AX7 -> 0 | EC7: 2 | ED7: 0 | EE7: =SUM(EC7:ED7) -> 2 | EF7: 0 | EG7: 0 | EH7: =SUM(EF7:EG7) -> 0 | EI7: =SUM(EC7+EF7) -> 2 | EJ7: =SUM(ED7+EG7) -> 0 | EK7: =SUM(EI7:EJ7) -> 2 | EW7: =SUM(ES7+EI7+DY7+DO7) -> 2 | EX7: =SUM(ET7+EJ7+DZ7+DP7) -> 0 | EY7: =SUM(EO7+EE7+DU7+DK7) -> 2 | EZ7: =SUM(ER7+EH7+DX7+DN7) -> 0 | FB7: =SUM(EW7:EX7) -> 2 | FD7: =DI7+DS7+EC7+EM7+CM7+CC7 -> 2 | FE7: =DJ7+DT7+ED7+EN7+CD7+CN7 -> 0 | FF7: =DL7+DV7+EF7+EP7+CP7+CF7 -> 0 | FG7: =DM7+DW7+EG7+EQ7+CG7+CQ7 -> 0 | FH7: =FD7+FF7 -> 2 | FI7: =FE7+FG7 -> 0 | FJ7: =FH7+FI7 -> 2 | FK7: =EW7+CW7+AS7 -> 2 | FL7: =EX7+CX7+AT7 -> 0 | FM7: =FK7+FL7 -> 2 | FN7: 0 | FO7: 0 | FP7: =SUM(FN7:FO7) -> 0 | FQ7: 0 | FR7: 0 | FS7: =SUM(FQ7:FR7) -> 0 | FT7: =FN7+FQ7 -> 0 | FU7: =FO7+FR7 -> 0 | FV7: =SUM(FT7:FU7) -> 0 | GD7: =FX7+GA7 -> 0 | GE7: =FY7+GB7 -> 0 | GF7: =GD7+GE7 -> 0 | GN7: =GH7+GK7 -> 0 | GO7: =GI7+GL7 -> 0 | GP7: =GN7+GO7 -> 0 | GR7: =GN7+GD7+FT7+ES7+EI7+DY7+DO7+CS7+CI7+BT7+BJ7 -> 2 | GS7: =GO7+GE7+FU7+ET7+EJ7+DZ7+DP7+CT7+CJ7+BU7+BK7 -> 0 | GT7: =GH7+FX7+FN7+EM7+EC7+DS7+DI7+CM7+CC7+BN7+BD7 -> 2 | GU7: =GI7+FY7+FO7+EN7+ED7+DT7+DJ7+CN7+CD7+BO7+BE7 -> 0 | GV7: =GK7+GA7+FQ7+EP7+EF7+DV7+DL7+CP7+CF7+BQ7+BG7 -> 0 | GW7: =GL7+GB7+FR7+EQ7+EG7+DW7+DM7+CQ7+CG7+BR7+BH7 -> 0 | GZ7: =GX7+GY7 -> 0 | HC7: =HA7+HB7 -> 0 | HD7: =GX7+HA7 -> 0 | HE7: =GY7+HB7 -> 0 | HF7: =HD7+HE7 -> 0 | HH7: =HD7+GN7+GD7+FT7 -> 0 | HI7: =GO7+GE7+FU7+HE7 -> 0 | HJ7: =GX7+GH7+FX7+FN7 -> 0 | HK7: =GI7+FY7+GY7+FO7 -> 0 | HL7: =GK7+GA7+FQ7+HA7 -> 0 | HM7: =GL7+HB7+GB7+FR7 -> 0 | HO7: =HF7+GP7+GF7+FV7 -> 0 | HQ7: =FN7+FX7+GH7+GX7 -> 0 | HR7: =FO7+FY7+GI7+GY7 -> 0 | HS7: =FQ7+GA7+GK7+HA7 -> 0 | HT7: =FR7+GB7+GL7+HB7 -> 0 | HW7: =HU7+HV7 -> 0 | HZ7: =HX7+HY7 -> 0 | IA7: =HU7+HX7 -> 0 | IB7: =HV7+HY7 -> 0 | IC7: =IA7+IB7 -> 0 | JN7: =JG7+IW7+IM7+IC7 -> 0 | JZ7: =JX7+JN7+HO7+FB7 -> 2 | KA7: =SUM(JV7+JE7+IU7+IK7+IA7+HD7+GN7+GD7+FT7+ES7+EI7+DY7+DO7+CS7+CI7+BT7+BJ7+AO7+AE7+U7+K7) -> 2 | KB7: =SUM(JW7+JF7+IV7+IL7+IB7+HE7+GO7+GE7+FU7+ET7+EJ7+DZ7+DP7+CT7+CJ7+BU7+BK7+AP7+AF7+V7+L7) -> 0 | KC7: =SUM(JP7+IY7+IO7+IE7+HU7+GX7+GH7+FX7+FN7+EM7+EC7+DS7+DI7+CM7+CC7+BN7+BD7+AI7+Y7+O7+E7) -> 2 | KD7: =SUM(JQ7+IZ7+IP7+IF7+HV7+GY7+GI7+FY7+FO7+EN7+ED7+DT7+DJ7+CN7+CD7+BO7+BE7+AJ7+Z7+P7+F7) -> 0 | KE7: =SUM(JS7+JB7+IR7+IH7+HX7+HA7+GK7+GA7+FQ7+EP7+EF7+DV7+DL7+CP7+CF7+BQ7+BG7+AL7+AB7+R7+H7) -> 0 | KF7: =SUM(JT7+JC7+IS7+II7+HY7+HB7+GL7+GB7+FR7+EQ7+EG7+DW7+DM7+CQ7+CG7+BR7+BH7+AM7+AC7+S7+I7) -> 0
B8: Provide in kind material support to GBV survivors (dignity kits) -(through referrals) | C8: Nakivale | D8: 100 | AI8: 2 | AJ8: 0 | AK8: =AI8+AJ8 -> 2 | AL8: 0 | AM8: 0 | AN8: =AL8+AM8 -> 0 | AO8: =AI8+AL8 -> 2 | AP8: =AJ8+AM8 -> 0 | AQ8: =AP8+AO8 -> 2 | AS8: =AO8+AE8+U8+K8 -> 2 | AT8: =AP8+AF8+V8+L8 -> 0 | AU8: =AK8+AA8+Q8+G8 -> 2 | AV8: =AN8 -> 0 | AX8: =SUM(AQ8+AG8+W8+M8) -> 2 | AZ8: =SUM(E8+O8+Y8+AI8) -> 2 | BA8: =F8+P8+Z8+AJ8 -> 0 | BB8: =H8+R8+AB8+AL8 -> 0 | BC8: =I8+S8+AC8+AM8 -> 0 | BD8: 2 | BE8: 0 | BF8: =BD8+BE8 -> 2 | BG8: 0 | BH8: 0 | BI8: =BG8+BH8 -> 0 | BJ8: =BD8+BG8 -> 2 | BK8: =BE8+BH8 -> 0 | BL8: =BJ8+BK8 -> 2 | BX8: =BN8+BD8+AI8+Y8+O8+E8 -> 4 | BY8: =BO8+BE8+AJ8+Z8+P8+F8 -> 0 | BZ8: =BQ8+BG8+AL8+AB8+R8+H8 -> 0 | CA8: =BR8+BH8+AM8+AC8+S8+I8 -> 0 | CB8: =BX8+BY8+BZ8+CA8 -> 4 | CC8: 4 | CD8: 0 | CE8: =SUM(CC8:CD8) -> 4 | CF8: 0 | CG8: 0 | CH8: =SUM(CF8:CG8) -> 0 | CI8: =SUM(CC8+CF8) -> 4 | CJ8: =SUM(CD8+CG8) -> 0 | CK8: =SUM(CI8:CJ8) -> 4 | CW8: =SUM(CS8+CI8+BT8+BJ8) -> 6 | CX8: =SUM(CT8+CJ8+BU8+BK8) -> 0 | CY8: =SUM(CU8+CK8+BV8+BL8) -> 6 | CZ8: =SUM(CR8+CH8+BS8+BI8) -> 0 | DA8: 1000 | DB8: =SUM(CW8:CX8) -> 6 | DD8: =BD8+BN8+CC8+CM8 -> 6 | DE8: =BE8+BO8+CD8+CN8 -> 0 | DF8: =BG8+BQ8+CF8+CP8 -> 0 | DG8: =BH8+BR8+CG8+CQ8 -> 0 | DH8: =DB8+AX8 -> 8 | DS8: 3 | DT8: 0 | DU8: =SUM(DS8:DT8) -> 3 | DV8: 0 | DW8: 0 | DX8: =SUM(DV8:DW8) -> 0 | DY8: =SUM(DS8+DV8) -> 3 | DZ8: =SUM(DT8+DW8) -> 0 | EA8: =SUM(DY8:DZ8) -> 3 | EC8: 21 | ED8: 0 | EE8: =SUM(EC8:ED8) -> 21 | EF8: 0 | EG8: 0 | EH8: =SUM(EF8:EG8) -> 0 | EI8: =SUM(EC8+EF8) -> 21 | EJ8: =SUM(ED8+EG8) -> 0 | EK8: =SUM(EI8:EJ8) -> 21 | EM8: 13 | EN8: 0 | EO8: =SUM(EM8:EN8) -> 13 | EP8: 0 | EQ8: 0 | ER8: =SUM(EP8:EQ8) -> 0 | ES8: =SUM(EM8+EP8) -> 13 | ET8: =SUM(EN8+EQ8) -> 0 | EU8: =SUM(ES8:ET8) -> 13 | EW8: =SUM(ES8+EI8+DY8+DO8) -> 37 | EX8: =SUM(ET8+EJ8+DZ8+DP8) -> 0 | EY8: =SUM(EO8+EE8+DU8+DK8) -> 37 | EZ8: =SUM(ER8+EH8+DX8+DN8) -> 0 | FB8: =SUM(EW8:EX8) -> 37 | FD8: =DI8+DS8+EC8+EM8+CM8+CC8 -> 41 | FE8: =DJ8+DT8+ED8+EN8+CD8+CN8 -> 0 | FF8: =DL8+DV8+EF8+EP8+CP8+CF8 -> 0 | FG8: =DM8+DW8+EG8+EQ8+CG8+CQ8 -> 0 | FH8: =FD8+FF8 -> 41 | FI8: =FE8+FG8 -> 0 | FJ8: =FH8+FI8 -> 41 | FK8: =EW8+CW8+AS8 -> 45 | FL8: =EX8+CX8+AT8 -> 0 | FM8: =FK8+FL8 -> 45 | FN8: 7 | FO8: 0 | FP8: =SUM(FN8:FO8) -> 7 | FQ8: 0 | FR8: 0 | FS8: =SUM(FQ8:FR8) -> 0 | FT8: =FN8+FQ8 -> 7 | FU8: =FO8+FR8 -> 0 | FV8: =SUM(FT8:FU8) -> 7 | GD8: =FX8+GA8 -> 0 | GE8: =FY8+GB8 -> 0 | GF8: =GD8+GE8 -> 0 | GN8: =GH8+GK8 -> 0 | GO8: =GI8+GL8 -> 0 | GP8: =GN8+GO8 -> 0 | GR8: =GN8+GD8+FT8+ES8+EI8+DY8+DO8+CS8+CI8+BT8+BJ8 -> 50 | GS8: =GO8+GE8+FU8+ET8+EJ8+DZ8+DP8+CT8+CJ8+BU8+BK8 -> 0 | GT8: =GH8+FX8+FN8+EM8+EC8+DS8+DI8+CM8+CC8+BN8+BD8 -> 50 | GU8: =GI8+FY8+FO8+EN8+ED8+DT8+DJ8+CN8+CD8+BO8+BE8 -> 0 | GV8: =GK8+GA8+FQ8+EP8+EF8+DV8+DL8+CP8+CF8+BQ8+BG8 -> 0 | GW8: =GL8+GB8+FR8+EQ8+EG8+DW8+DM8+CQ8+CG8+BR8+BH8 -> 0 | GZ8: =GX8+GY8 -> 0 | HC8: =HA8+HB8 -> 0 | HD8: =GX8+HA8 -> 0 | HE8: =GY8+HB8 -> 0 | HF8: =HD8+HE8 -> 0 | HH8: =HD8+GN8+GD8+FT8 -> 7 | HI8: =GO8+GE8+FU8+HE8 -> 0 | HJ8: =GX8+GH8+FX8+FN8 -> 7 | HK8: =GI8+FY8+GY8+FO8 -> 0 | HL8: =GK8+GA8+FQ8+HA8 -> 0 | HM8: =GL8+HB8+GB8+FR8 -> 0 | HN8: 100 | HO8: =HF8+GP8+GF8+FV8 -> 7 | HQ8: =FN8+FX8+GH8+GX8 -> 7 | HR8: =FO8+FY8+GI8+GY8 -> 0 | HS8: =FQ8+GA8+GK8+HA8 -> 0 | HT8: =FR8+GB8+GL8+HB8 -> 0 | HW8: =HU8+HV8 -> 0 | HZ8: =HX8+HY8 -> 0 | IA8: =HU8+HX8 -> 0 | IB8: =HV8+HY8 -> 0 | IC8: =IA8+IB8 -> 0 | JI8: =SUM(JE8+IU8+IK8+IA8) -> 0 | JJ8: 0 | JM8: 100 | JN8: =JG8+IW8+IM8+IC8 -> 0 | JZ8: =JX8+JN8+HO8+FB8 -> 44 | KA8: =SUM(JV8+JE8+IU8+IK8+IA8+HD8+GN8+GD8+FT8+ES8+EI8+DY8+DO8+CS8+CI8+BT8+BJ8+AO8+AE8+U8+K8) -> 52 | KB8: =SUM(JW8+JF8+IV8+IL8+IB8+HE8+GO8+GE8+FU8+ET8+EJ8+DZ8+DP8+CT8+CJ8+BU8+BK8+AP8+AF8+V8+L8) -> 0 | KC8: =SUM(JP8+IY8+IO8+IE8+HU8+GX8+GH8+FX8+FN8+EM8+EC8+DS8+DI8+CM8+CC8+BN8+BD8+AI8+Y8+O8+E8) -> 52 | KD8: =SUM(JQ8+IZ8+IP8+IF8+HV8+GY8+GI8+FY8+FO8+EN8+ED8+DT8+DJ8+CN8+CD8+BO8+BE8+AJ8+Z8+P8+F8) -> 0 | KE8: =SUM(JS8+JB8+IR8+IH8+HX8+HA8+GK8+GA8+FQ8+EP8+EF8+DV8+DL8+CP8+CF8+BQ8+BG8+AL8+AB8+R8+H8) -> 0 | KF8: =SUM(JT8+JC8+IS8+II8+HY8+HB8+GL8+GB8+FR8+EQ8+EG8+DW8+DM8+CQ8+CG8+BR8+BH8+AM8+AC8+S8+I8) -> 0 | KG8: =SUM(KA8:KB8) -> 52 | KH8: 100 | KI8: =KH8-KG8 -> 48 | KJ8: =KG8/KH8 -> 0.52
B9: GBV Case Conferencing | C9: Nakivale | D9: 9 | T9: =SUM(R9:S9) -> 0 | U9: =SUM(O9+R9) -> 0 | V9: =SUM(P9+S9) -> 0 | W9: =SUM(U9:V9) -> 0 | AO9: =SUM(AI9+AL9) -> 0 | AP9: =SUM(AJ9+AM9) -> 0 | AQ9: =SUM(AO9:AP9) -> 0 | AS9: =AO9+AE9+U9+K9 -> 0 | AT9: =AP9+AF9+V9+L9 -> 0 | AU9: =AK9+AA9+Q9+G9 -> 0 | AV9: =AN9 -> 0 | AX9: =SUM(AQ9+AG9+W9+M9) -> 0 | AY9: =AX9/AW9 -> #DIV/0! | AZ9: =SUM(E9+O9+Y9+AI9) -> 0 | BA9: =F9+P9+Z9+AJ9 -> 0 | BB9: =H9+R9+AB9+AL9 -> 0 | BC9: =I9+S9+AC9+AM9 -> 0 | BF9: =SUM(BD9:BE9) -> 0 | BI9: =SUM(BG9:BH9) -> 0 | BJ9: =SUM(BD9+BG9) -> 0 | BK9: =SUM(BE9+BH9) -> 0 | BL9: 1 | BS9: =SUM(BQ9:BR9) -> 0 | BT9: =SUM(BN9+BQ9) -> 0 | BU9: =SUM(BO9+BR9) -> 0 | BV9: =SUM(BT9:BU9) -> 0 | BX9: =BN9+BD9+AI9+Y9+O9+E9 -> 0 | BY9: =BO9+BE9+AJ9+Z9+P9+F9 -> 0 | BZ9: =BQ9+BG9+AL9+AB9+R9+H9 -> 0 | CA9: =BR9+BH9+AM9+AC9+S9+I9 -> 0 | CB9: =BX9+BY9+BZ9+CA9 -> 0 | CH9: =SUM(CF9:CG9) -> 0 | CI9: =SUM(CC9+CF9) -> 0 | CJ9: =SUM(CD9+CG9) -> 0 | CK9: =SUM(CI9:CJ9) -> 0 | CR9: =SUM(CP9:CQ9) -> 0 | CS9: =SUM(CM9+CP9) -> 0 | CT9: =SUM(CN9+CQ9) -> 0 | CU9: =SUM(CS9:CT9) -> 0 | CW9: =SUM(CS9+CI9+BT9+BJ9) -> 0 | CX9: =SUM(CT9+CJ9+BU9+BK9) -> 0 | CY9: =SUM(CU9+CK9+BV9+BL9) -> 1 | CZ9: =SUM(CR9+CH9+BS9+BI9) -> 0 | DA9: 9 | DB9: =SUM(CW9:CX9) -> 0 | DC9: =DB9/DA9 -> 0 | DD9: =BD9+BN9+CC9+CM9 -> 0 | DE9: =BE9+BO9+CD9+CN9 -> 0 | DF9: =BG9+BQ9+CF9+CP9 -> 0 | DG9: =BH9+BR9+CG9+CQ9 -> 0 | DH9: =DB9+AX9 -> 0 | DN9: =SUM(DL9:DM9) -> 0 | DO9: =SUM(DI9+DL9) -> 0 | DP9: =SUM(DJ9+DM9) -> 0 | DQ9: =SUM(DO9:DP9) -> 0 | DU9: =SUM(DS9:DT9) -> 0 | DX9: =SUM(DV9:DW9) -> 0 | DY9: =SUM(DS9+DV9) -> 0 | DZ9: =SUM(DT9+DW9) -> 0 | EA9: =SUM(DY9:DZ9) -> 0 | EH9: =SUM(EF9:EG9) -> 0 | EI9: =SUM(EC9+EF9) -> 0 | EJ9: =SUM(ED9+EG9) -> 0 | EK9: 0 | ER9: =SUM(EP9:EQ9) -> 0 | ES9: =SUM(EM9+EP9) -> 0 | ET9: =SUM(EN9+EQ9) -> 0 | EU9: 1 | EW9: =SUM(ES9+EI9+DY9+DO9) -> 0 | EX9: =SUM(ET9+EJ9+DZ9+DP9) -> 0 | EY9: =SUM(EO9+EE9+DU9+DK9) -> 0 | EZ9: =SUM(ER9+EH9+DX9+DN9) -> 0 | FB9: 1 | FC9: =FB9/FA9 -> #DIV/0! | FD9: =DI9+DS9+EC9+EM9+CM9+CC9 -> 0 | FE9: =DJ9+DT9+ED9+EN9+CD9+CN9 -> 0 | FF9: =DL9+DV9+EF9+EP9+CP9+CF9 -> 0 | FG9: =DM9+DW9+EG9+EQ9+CG9+CQ9 -> 0 | FH9: =FD9+FF9 -> 0 | FI9: =FE9+FG9 -> 0 | FJ9: 2 | FK9: =EW9+CW9+AS9 -> 0 | FL9: =EX9+CX9+AT9 -> 0 | FM9: =FK9+FL9 -> 0 | FN9: 0 | FO9: 0 | FP9: =SUM(FN9:FO9) -> 0 | FQ9: 0 | FR9: 0 | FS9: =SUM(FQ9:FR9) -> 0 | FT9: =FN9+FQ9 -> 0 | FU9: =FO9+FR9 -> 0 | FV9: =SUM(FT9:FU9) -> 0 | GC9: =SUM(GA9:GB9) -> 0 | GD9: =FX9+GA9 -> 0 | GE9: =FY9+GB9 -> 0 | GF9: =GD9+GE9 -> 0 | GM9: =SUM(GK9:GL9) -> 0 | GN9: =GH9+GK9 -> 0 | GO9: =GI9+GL9 -> 0 | GP9: =GN9+GO9 -> 0 | GR9: =GN9+GD9+FT9+ES9+EI9+DY9+DO9+CS9+CI9+BT9+BJ9 -> 0 | GS9: =GO9+GE9+FU9+ET9+EJ9+DZ9+DP9+CT9+CJ9+BU9+BK9 -> 0 | GT9: =GH9+FX9+FN9+EM9+EC9+DS9+DI9+CM9+CC9+BN9+BD9 -> 0 | GU9: =GI9+FY9+FO9+EN9+ED9+DT9+DJ9+CN9+CD9+BO9+BE9 -> 0 | GV9: =GK9+GA9+FQ9+EP9+EF9+DV9+DL9+CP9+CF9+BQ9+BG9 -> 0 | GW9: =GL9+GB9+FR9+EQ9+EG9+DW9+DM9+CQ9+CG9+BR9+BH9 -> 0 | GZ9: =GX9+GY9 -> 0 | HC9: =HA9+HB9 -> 0 | HD9: =GX9+HA9 -> 0 | HE9: =GY9+HB9 -> 0 | HF9: =HD9+HE9 -> 0 | HH9: =HD9+GN9+GD9+FT9 -> 0 | HI9: =GO9+GE9+FU9+HE9 -> 0 | HJ9: =GX9+GH9+FX9+FN9 -> 0 | HK9: =GI9+FY9+GY9+FO9 -> 0 | HL9: =GK9+GA9+FQ9+HA9 -> 0 | HM9: =GL9+HB9+GB9+FR9 -> 0 | HO9: =HF9+GP9+GF9+FV9 -> 0 | HP9: =HO9/HN9 -> #DIV/0! | HQ9: =FN9+FX9+GH9+GX9 -> 0 | HR9: =FO9+FY9+GI9+GY9 -> 0 | HS9: =FQ9+GA9+GK9+HA9 -> 0 | HT9: =FR9+GB9+GL9+HB9 -> 0 | HW9: =HU9+HV9 -> 0 | HZ9: =HX9+HY9 -> 0 | IA9: =HU9+HX9 -> 0 | IB9: =HV9+HY9 -> 0 | IC9: =IA9+IB9 -> 0 | IJ9: =SUM(IH9:II9) -> 0 | IK9: =SUM(IE9+IH9) -> 0 | IL9: =SUM(IF9+II9) -> 0 | IM9: =SUM(IK9:IL9) -> 0 | IT9: =SUM(IR9:IS9) -> 0 | IU9: =SUM(IO9+IR9) -> 0 | IV9: =SUM(IP9+IS9) -> 0 | IW9: =SUM(IU9:IV9) -> 0 | JD9: =SUM(JB9:JC9) -> 0 | JE9: =SUM(IY9+JB9) -> 0 | JF9: =SUM(IZ9+JC9) -> 0 | JG9: =SUM(JE9:JF9) -> 0 | JI9: =SUM(IA9+IK9+IU9) -> 0 | JJ9: =SUM(IB9+IL9+IV9) -> 0 | JK9: =SUM(IG9+IQ9+HW9) -> 0 | JL9: =SUM(HZ9+IJ9+IT9) -> 0 | JN9: =JG9+IW9+IM9+IC9 -> 0 | JO9: =JN9/JM9 -> #DIV/0! | JU9: =SUM(JS9:JT9) -> 0 | JV9: =SUM(JP9+JS9) -> 0 | JW9: =SUM(JQ9+JT9) -> 0 | JX9: =SUM(JV9:JW9) -> 0 | JZ9: =JX9+JN9+HO9+FB9 -> 1 | KA9: =SUM(JV9+JE9+IU9+IK9+IA9+HD9+GN9+GD9+FT9+ES9+EI9+DY9+DO9+CS9+CI9+BT9+BJ9+AO9+AE9+U9+K9) -> 0 | KB9: =SUM(JW9+JF9+IV9+IL9+IB9+HE9+GO9+GE9+FU9+ET9+EJ9+DZ9+DP9+CT9+CJ9+BU9+BK9+AP9+AF9+V9+L9) -> 0 | KC9: =SUM(JP9+IY9+IO9+IE9+HU9+GX9+GH9+FX9+FN9+EM9+EC9+DS9+DI9+CM9+CC9+BN9+BD9+AI9+Y9+O9+E9) -> 0 | KD9: =SUM(JQ9+IZ9+IP9+IF9+HV9+GY9+GI9+FY9+FO9+EN9+ED9+DT9+DJ9+CN9+CD9+BO9+BE9+AJ9+Z9+P9+F9) -> 0 | KE9: 2 | KF9: =SUM(JT9+JC9+IS9+II9+HY9+HB9+GL9+GB9+FR9+EQ9+EG9+DW9+DM9+CQ9+CG9+BR9+BH9+AM9+AC9+S9+I9) -> 0 | KG9: 2 | KH9: 9 | KI9: =KH9-KG9 -> 7 | KJ9: =KG9/KH9 -> 0.22222222
A10: Indicator 2 Number of participants showing an increased knowledge on the protection subject in focus | B10: Training GBVCommunity Structures | C10: Nakivale | D10: 130 | Y10: 16 | Z10: 17 | AA10: =SUM(Y10:Z10) -> 33 | AB10: 7 | AC10: 5 | AD10: =SUM(AB10:AC10) -> 12 | AE10: =SUM(Y10+AB10) -> 23 | AF10: =SUM(Z10+AC10) -> 22 | AG10: =SUM(AE10:AF10) -> 45 | AS10: =AO10+AE10+U10+K10 -> 23 | AT10: =AP10+AF10+V10+L10 -> 22 | AU10: =AK10+AA10+Q10+G10 -> 33 | AV10: =AN10 -> 0 | AX10: =SUM(AQ10+AG10+W10+M10) -> 45 | AY10: =AX10/AW10 -> #DIV/0! | AZ10: =SUM(E10+O10+Y10+AI10) -> 16 | BA10: =F10+P10+Z10+AJ10 -> 17 | BB10: =H10+R10+AB10+AL10 -> 7 | BC10: =I10+S10+AC10+AM10 -> 5 | BD10: 20 | BE10: 20 | BF10: =SUM(BD10:BE10) -> 40 | BG10: 0 | BH10: 0 | BI10: =SUM(BG10:BH10) -> 0 | BJ10: =SUM(BD10+BG10) -> 20 | BK10: =SUM(BE10+BH10) -> 20 | BL10: =SUM(BJ10:BK10) -> 40 | BM10: 1 | BX10: =BN10+BD10+AI10+Y10+O10+E10 -> 36 | BY10: =BO10+BE10+AJ10+Z10+P10+F10 -> 37 | BZ10: =BQ10+BG10+AL10+AB10+R10+H10 -> 7 | CA10: =BR10+BH10+AM10+AC10+S10+I10 -> 5 | CB10: =BX10+BY10+BZ10+CA10 -> 85 | CW10: =SUM(CS10+CI10+BT10+BJ10) -> 20 | CX10: =SUM(CT10+CJ10+BU10+BK10) -> 20 | CY10: =SUM(CU10+CK10+BV10+BL10) -> 40 | CZ10: =SUM(CR10+CH10+BS10+BI10) -> 0 | DB10: =SUM(CW10:CX10) -> 40 | DC10: =DB10/DA10 -> #DIV/0! | DD10: =BD10+BN10+CC10+CM10 -> 20 | DE10: =BE10+BO10+CD10+CN10 -> 20 | DF10: =BG10+BQ10+CF10+CP10 -> 0 | DG10: =BH10+BR10+CG10+CQ10 -> 0 | DH10: =DB10+AX10 -> 85 | DU10: =SUM(DS10:DT10) -> 0 | DX10: =SUM(DV10:DW10) -> 0 | DY10: =SUM(DS10+DV10) -> 0 | DZ10: =SUM(DT10+DW10) -> 0 | EA10: =SUM(DY10:DZ10) -> 0 | EU10: 0 | EW10: =SUM(ES10+EI10+DY10+DO10) -> 0 | EX10: =SUM(ET10+EJ10+DZ10+DP10) -> 0 | EY10: =SUM(EO10+EE10+DU10+DK10) -> 0 | EZ10: =SUM(ER10+EH10+DX10+DN10) -> 0 | FB10: =SUM(EW10:EX10) -> 0 | FC10: =FB10/FA10 -> #DIV/0! | FD10: =DI10+DS10+EC10+EM10+CM10+CC10 -> 0 | FE10: =DJ10+DT10+ED10+EN10+CD10+CN10 -> 0 | FF10: =DL10+DV10+EF10+EP10+CP10+CF10 -> 0 | FG10: =DM10+DW10+EG10+EQ10+CG10+CQ10 -> 0 | FH10: =FD10+FF10 -> 0 | FI10: =FE10+FG10 -> 0 | FJ10: =FH10+FI10 -> 0 | FK10: =EW10+CW10+AS10 -> 43 | FL10: =EX10+CX10+AT10 -> 42 | FM10: =FK10+FL10 -> 85 | FN10: 0 | FO10: 0 | FP10: =SUM(FN10:FO10) -> 0 | FQ10: 0 | FR10: 0 | FS10: =SUM(FQ10:FR10) -> 0 | FT10: =FN10+FQ10 -> 0 | FU10: =FO10+FR10 -> 0 | FV10: =SUM(FT10:FU10) -> 0 | FX10: 5 | FY10: 7 | FZ10: =SUM(FX10:FY10) -> 12 | GA10: 0 | GB10: 0 | GC10: =SUM(GA10:GB10) -> 0 | GD10: =FX10+GA10 -> 5 | GE10: =FY10+GB10 -> 7 | GF10: =GD10+GE10 -> 12 | GN10: =GH10+GK10 -> 0 | GO10: =GI10+GL10 -> 0 | GP10: =GN10+GO10 -> 0 | GR10: =GN10+GD10+FT10+ES10+EI10+DY10+DO10+CS10+CI10+BT10+BJ10 -> 25 | GS10: =GO10+GE10+FU10+ET10+EJ10+DZ10+DP10+CT10+CJ10+BU10+BK10 -> 27 | GT10: =GH10+FX10+FN10+EM10+EC10+DS10+DI10+CM10+CC10+BN10+BD10 -> 25 | GU10: =GI10+FY10+FO10+EN10+ED10+DT10+DJ10+CN10+CD10+BO10+BE10 -> 27 | GV10: =GK10+GA10+FQ10+EP10+EF10+DV10+DL10+CP10+CF10+BQ10+BG10 -> 0 | GW10: =GL10+GB10+FR10+EQ10+EG10+DW10+DM10+CQ10+CG10+BR10+BH10 -> 0 | GZ10: =GX10+GY10 -> 0 | HC10: =HA10+HB10 -> 0 | HD10: =GX10+HA10 -> 0 | HE10: =GY10+HB10 -> 0 | HF10: =HD10+HE10 -> 0 | HH10: =HD10+GN10+GD10+FT10 -> 5 | HI10: =GO10+GE10+FU10+HE10 -> 7 | HJ10: =GX10+GH10+FX10+FN10 -> 5 | HK10: =GI10+FY10+GY10+FO10 -> 7 | HL10: =GK10+GA10+FQ10+HA10 -> 0 | HM10: =GL10+HB10+GB10+FR10 -> 0 | HO10: =HF10+GP10+GF10+FV10 -> 12 | HP10: =HO10/HN10 -> #DIV/0! | HQ10: =FN10+FX10+GH10+GX10 -> 5 | HR10: =FO10+FY10+GI10+GY10 -> 7 | HS10: =FQ10+GA10+GK10+HA10 -> 0 | HT10: =FR10+GB10+GL10+HB10 -> 0 | HW10: =HU10+HV10 -> 0 | HZ10: =HX10+HY10 -> 0 | IA10: =HU10+HX10 -> 0 | IB10: =HV10+HY10 -> 0 | IC10: =IA10+IB10 -> 0 | JN10: =JG10+IW10+IM10+IC10 -> 0 | JO10: =JN10/JM10 -> #DIV/0! | JZ10: =JX10+JN10+HO10+FB10 -> 12 | KA10: =SUM(JV10+JE10+IU10+IK10+IA10+HD10+GN10+GD10+FT10+ES10+EI10+DY10+DO10+CS10+CI10+BT10+BJ10+AO10+AE10+U10+K10) -> 48 | KB10: =SUM(JW10+JF10+IV10+IL10+IB10+HE10+GO10+GE10+FU10+ET10+EJ10+DZ10+DP10+CT10+CJ10+BU10+BK10+AP10+AF10+V10+L10) -> 49 | KC10: =SUM(JP10+IY10+IO10+IE10+HU10+GX10+GH10+FX10+FN10+EM10+EC10+DS10+DI10+CM10+CC10+BN10+BD10+AI10+Y10+O10+E10) -> 41 | KD10: =SUM(JQ10+IZ10+IP10+IF10+HV10+GY10+GI10+FY10+FO10+EN10+ED10+DT10+DJ10+CN10+CD10+BO10+BE10+AJ10+Z10+P10+F10) -> 44 | KE10: =SUM(JS10+JB10+IR10+IH10+HX10+HA10+GK10+GA10+FQ10+EP10+EF10+DV10+DL10+CP10+CF10+BQ10+BG10+AL10+AB10+R10+H10) -> 7 | KF10: =SUM(JT10+JC10+IS10+II10+HY10+HB10+GL10+GB10+FR10+EQ10+EG10+DW10+DM10+CQ10+CG10+BR10+BH10+AM10+AC10+S10+I10) -> 5 | KG10: =SUM(KA10:KB10) -> 97 | KH10: 130 | KI10: =KH10-KG10 -> 33 | KJ10: =KG10/KH10 -> 0.74615385
B11: Clinical Health Training for 30 health workers, clinical care sexual assault. 30 police officers | C11: Nakivale | D11: 60 | T11: =SUM(R11:S11) -> 0 | U11: =SUM(O11+R11) -> 0 | V11: =SUM(P11+S11) -> 0 | W11: =SUM(U11:V11) -> 0 | AA11: =SUM(Y11:Z11) -> 0 | AD11: =SUM(AB11:AC11) -> 0 | AE11: =SUM(Y11+AB11) -> 0 | AF11: =SUM(Z11+AC11) -> 0 | AG11: =SUM(AE11:AF11) -> 0 | AS11: =AO11+AE11+U11+K11 -> 0 | AT11: =AP11+AF11+V11+L11 -> 0 | AU11: =AK11+AA11+Q11+G11 -> 0 | AV11: =AN11 -> 0 | AX11: =SUM(AQ11+AG11+W11+M11) -> 0 | AY11: =AX11/AW11 -> #DIV/0! | AZ11: =SUM(E11+O11+Y11+AI11) -> 0 | BA11: =F11+P11+Z11+AJ11 -> 0 | BB11: =H11+R11+AB11+AL11 -> 0 | BC11: =I11+S11+AC11+AM11 -> 0 | BX11: =BN11+BD11+AI11+Y11+O11+E11 -> 0 | BY11: =BO11+BE11+AJ11+Z11+P11+F11 -> 0 | BZ11: =BQ11+BG11+AL11+AB11+R11+H11 -> 0 | CA11: =BR11+BH11+AM11+AC11+S11+I11 -> 0 | CB11: =BX11+BY11+BZ11+CA11 -> 0 | CW11: =SUM(CS11+CI11+BT11+BJ11) -> 0 | CX11: =SUM(CT11+CJ11+BU11+BK11) -> 0 | CY11: =SUM(CU11+CK11+BV11+BL11) -> 0 | CZ11: =SUM(CR11+CH11+BS11+BI11) -> 0 | DB11: =SUM(CW11:CX11) -> 0 | DC11: =DB11/DA11 -> #DIV/0! | DD11: =BD11+BN11+CC11+CM11 -> 0 | DE11: =BE11+BO11+CD11+CN11 -> 0 | DF11: =BG11+BQ11+CF11+CP11 -> 0 | DG11: =BH11+BR11+CG11+CQ11 -> 0 | DH11: =DB11+AX11 -> 0 | DU11: =SUM(DS11:DT11) -> 0 | DX11: =SUM(DV11:DW11) -> 0 | DY11: =SUM(DS11+DV11) -> 0 | DZ11: =SUM(DT11+DW11) -> 0 | EA11: =SUM(DY11:DZ11) -> 0 | EW11: =SUM(ES11+EI11+DY11+DO11) -> 0 | EX11: =SUM(ET11+EJ11+DZ11+DP11) -> 0 | EY11: =SUM(EO11+EE11+DU11+DK11) -> 0 | EZ11: =SUM(ER11+EH11+DX11+DN11) -> 0 | FB11: =SUM(EW11:EX11) -> 0 | FC11: =FB11/FA11 -> #DIV/0! | FD11: =DI11+DS11+EC11+EM11+CM11+CC11 -> 0 | FE11: =DJ11+DT11+ED11+EN11+CD11+CN11 -> 0 | FF11: =DL11+DV11+EF11+EP11+CP11+CF11 -> 0 | FG11: =DM11+DW11+EG11+EQ11+CG11+CQ11 -> 0 | FH11: =FD11+FF11 -> 0 | FI11: =FE11+FG11 -> 0 | FJ11: =FH11+FI11 -> 0 | FK11: =EW11+CW11+AS11 -> 0 | FL11: =EX11+CX11+AT11 -> 0 | FM11: =FK11+FL11 -> 0 | FN11: 0 | FO11: 0 | FP11: =SUM(FN11:FO11) -> 0 | FQ11: 0 | FR11: 0 | FS11: =SUM(FQ11:FR11) -> 0 | FT11: =FN11+FQ11 -> 0 | FU11: =FO11+FR11 -> 0 | FV11: =SUM(FT11:FU11) -> 0 | GD11: =FX11+GA11 -> 0 | GE11: =FY11+GB11 -> 0 | GF11: =GD11+GE11 -> 0 | GN11: =GH11+GK11 -> 0 | GO11: =GI11+GL11 -> 0 | GP11: =GN11+GO11 -> 0 | GR11: =GN11+GD11+FT11+ES11+EI11+DY11+DO11+CS11+CI11+BT11+BJ11 -> 0 | GS11: =GO11+GE11+FU11+ET11+EJ11+DZ11+DP11+CT11+CJ11+BU11+BK11 -> 0 | GT11: =GH11+FX11+FN11+EM11+EC11+DS11+DI11+CM11+CC11+BN11+BD11 -> 0 | GU11: =GI11+FY11+FO11+EN11+ED11+DT11+DJ11+CN11+CD11+BO11+BE11 -> 0 | GV11: =GK11+GA11+FQ11+EP11+EF11+DV11+DL11+CP11+CF11+BQ11+BG11 -> 0 | GW11: =GL11+GB11+FR11+EQ11+EG11+DW11+DM11+CQ11+CG11+BR11+BH11 -> 0 | GZ11: =GX11+GY11 -> 0 | HC11: =HA11+HB11 -> 0 | HD11: =GX11+HA11 -> 0 | HE11: =GY11+HB11 -> 0 | HF11: =HD11+HE11 -> 0 | HH11: =HD11+GN11+GD11+FT11 -> 0 | HI11: =GO11+GE11+FU11+HE11 -> 0 | HJ11: =GX11+GH11+FX11+FN11 -> 0 | HK11: =GI11+FY11+GY11+FO11 -> 0 | HL11: =GK11+GA11+FQ11+HA11 -> 0 | HM11: =GL11+HB11+GB11+FR11 -> 0 | HO11: =HF11+GP11+GF11+FV11 -> 0 | HP11: =HO11/HN11 -> #DIV/0! | HQ11: =FN11+FX11+GH11+GX11 -> 0 | HR11: =FO11+FY11+GI11+GY11 -> 0 | HS11: =FQ11+GA11+GK11+HA11 -> 0 | HT11: =FR11+GB11+GL11+HB11 -> 0 | HW11: =HU11+HV11 -> 0 | HZ11: =HX11+HY11 -> 0 | IA11: =HU11+HX11 -> 0 | IB11: =HV11+HY11 -> 0 | IC11: =IA11+IB11 -> 0 | JI11: =SUM(IA11+IK11+IU11) -> 0 | JJ11: =SUM(IB11+IL11+IV11) -> 0 | JK11: =SUM(HW11+IG11+IQ11) -> 0 | JL11: =SUM(IJ11+IC11+IT11) -> 0 | JN11: =JG11+IW11+IM11+IC11 -> 0 | JO11: =JN11/JM11 -> #DIV/0! | JZ11: =JX11+JN11+HO11+FB11 -> 0 | KA11: =SUM(JV11+JE11+IU11+IK11+IA11+HD11+GN11+GD11+FT11+ES11+EI11+DY11+DO11+CS11+CI11+BT11+BJ11+AO11+AE11+U11+K11) -> 0 | KB11: =SUM(JW11+JF11+IV11+IL11+IB11+HE11+GO11+GE11+FU11+ET11+EJ11+DZ11+DP11+CT11+CJ11+BU11+BK11+AP11+AF11+V11+L11) -> 0 | KC11: =SUM(JP11+IY11+IO11+IE11+HU11+GX11+GH11+FX11+FN11+EM11+EC11+DS11+DI11+CM11+CC11+BN11+BD11+AI11+Y11+O11+E11) -> 0 | KD11: =SUM(JQ11+IZ11+IP11+IF11+HV11+GY11+GI11+FY11+FO11+EN11+ED11+DT11+DJ11+CN11+CD11+BO11+BE11+AJ11+Z11+P11+F11) -> 0 | KE11: =SUM(JS11+JB11+IR11+IH11+HX11+HA11+GK11+GA11+FQ11+EP11+EF11+DV11+DL11+CP11+CF11+BQ11+BG11+AL11+AB11+R11+H11) -> 0 | KF11: =SUM(JT11+JC11+IS11+II11+HY11+HB11+GL11+GB11+FR11+EQ11+EG11+DW11+DM11+CQ11+CG11+BR11+BH11+AM11+AC11+S11+I11) -> 0 | KG11: =SUM(KA11:KB11) -> 0 | KH11: 60 | KI11: =KH11-KG11 -> 60 | KJ11: =KG11/KH11 -> 0
B12: Training WGSS CMCS on leadership and safe space management and income generating activities [IGA] | C12: Nakivale | D12: 25 | O12: 0 | P12: 0 | Q12: =SUM(O12:P12) -> 0 | T12: =SUM(R12:S12) -> 0 | U12: =SUM(O12+R12) -> 0 | V12: =SUM(P12+S12) -> 0 | W12: =SUM(U12:V12) -> 0 | AA12: =SUM(Y12:Z12) -> 0 | AD12: =SUM(AB12:AC12) -> 0 | AE12: =SUM(Y12+AB12) -> 0 | AF12: =SUM(Z12+AC12) -> 0 | AG12: =SUM(AE12:AF12) -> 0 | AK12: =SUM(AI12:AJ12) -> 0 | AN12: =SUM(AL12:AM12) -> 0 | AO12: =SUM(AI12+AL12) -> 0 | AP12: =SUM(AJ12+AM12) -> 0 | AQ12: =SUM(AO12:AP12) -> 0 | AS12: =AO12+AE12+U12+K12 -> 0 | AT12: =AP12+AF12+V12+L12 -> 0 | AU12: =AK12+AA12+Q12+G12 -> 0 | AV12: =AN12 -> 0 | AX12: =SUM(AQ12+AG12+W12+M12) -> 0 | AY12: =AX12/AW12 -> #DIV/0! | AZ12: =SUM(E12+O12+Y12+AI12) -> 0 | BA12: =F12+P12+Z12+AJ12 -> 0 | BB12: =H12+R12+AB12+AL12 -> 0 | BC12: =I12+S12+AC12+AM12 -> 0 | BI12: =SUM(BG12:BH12) -> 0 | BJ12: =SUM(BD12+BG12) -> 0 | BK12: =SUM(BE12+BH12) -> 0 | BL12: =SUM(BJ12:BK12) -> 0 | BS12: =SUM(BQ12:BR12) -> 0 | BT12: =SUM(BN12+BQ12) -> 0 | BU12: =SUM(BO12+BR12) -> 0 | BV12: =SUM(BT12:BU12) -> 0 | BX12: =BN12+BD12+AI12+Y12+O12+E12 -> 0 | BY12: =BO12+BE12+AJ12+Z12+P12+F12 -> 0 | BZ12: =BQ12+BG12+AL12+AB12+R12+H12 -> 0 | CA12: =BR12+BH12+AM12+AC12+S12+I12 -> 0 | CB12: =BX12+BY12+BZ12+CA12 -> 0 | CH12: =SUM(CF12:CG12) -> 0 | CI12: =SUM(CC12+CF12) -> 0 | CJ12: =SUM(CD12+CG12) -> 0 | CK12: =SUM(CI12:CJ12) -> 0 | CR12: =SUM(CP12:CQ12) -> 0 | CS12: =SUM(CM12+CP12) -> 0 | CT12: =SUM(CN12+CQ12) -> 0 | CU12: =SUM(CS12:CT12) -> 0 | CW12: =SUM(CS12+CI12+BT12+BJ12) -> 0 | CX12: =SUM(CT12+CJ12+BU12+BK12) -> 0 | CY12: =SUM(CU12+CK12+BV12+BL12) -> 0 | CZ12: =SUM(CR12+CH12+BS12+BI12) -> 0 | DB12: =SUM(CW12:CX12) -> 0 | DC12: =DB12/DA12 -> #DIV/0! | DD12: =BD12+BN12+CC12+CM12 -> 0 | DE12: =BE12+BO12+CD12+CN12 -> 0 | DF12: =BG12+BQ12+CF12+CP12 -> 0 | DG12: =BH12+BR12+CG12+CQ12 -> 0 | DH12: =DB12+AX12 -> 0 | DN12: =SUM(DL12:DM12) -> 0 | DO12: =SUM(DI12+DL12) -> 0 | DP12: =SUM(DJ12+DM12) -> 0 | DQ12: =SUM(DO12:DP12) -> 0 | DU12: =SUM(DS12:DT12) -> 0 | DX12: =SUM(DV12:DW12) -> 0 | DY12: =SUM(DS12+DV12) -> 0 | DZ12: =SUM(DT12+DW12) -> 0 | EA12: =SUM(DY12:DZ12) -> 0 | EH12: =SUM(EF12:EG12) -> 0 | EI12: =SUM(EC12+EF12) -> 0 | EJ12: =SUM(ED12+EG12) -> 0 | EK12: =SUM(EI12:EJ12) -> 0 | EM12: 26 | EN12: 0 | EO12: =SUM(EM12:EN12) -> 26 | EP12: 1 | EQ12: 0 | ER12: =SUM(EP12:EQ12) -> 1 | ES12: =SUM(EM12+EP12) -> 27 | ET12: =SUM(EN12+EQ12) -> 0 | EU12: =SUM(ES12:ET12) -> 27 | EW12: =SUM(ES12+EI12+DY12+DO12) -> 27 | EX12: =SUM(ET12+EJ12+DZ12+DP12) -> 0 | EY12: =SUM(EO12+EE12+DU12+DK12) -> 26 | EZ12: =SUM(ER12+EH12+DX12+DN12) -> 1 | FB12: =SUM(EW12:EX12) -> 27 | FC12: =FB12/FA12 -> #DIV/0! | FD12: =DI12+DS12+EC12+EM12+CM12+CC12 -> 26 | FE12: =DJ12+DT12+ED12+EN12+CD12+CN12 -> 0 | FF12: =DL12+DV12+EF12+EP12+CP12+CF12 -> 1 | FG12: =DM12+DW12+EG12+EQ12+CG12+CQ12 -> 0 | FH12: =FD12+FF12 -> 27 | FI12: =FE12+FG12 -> 0 | FJ12: =FH12+FI12 -> 27 | FK12: =EW12+CW12+AS12 -> 27 | FL12: =EX12+CX12+AT12 -> 0 | FM12: =FK12+FL12 -> 27 | FS12: =SUM(FQ12:FR12) -> 0 | FT12: =SUM(FN12+FQ12) -> 0 | FU12: =SUM(FO12+FR12) -> 0 | FV12: =SUM(FT12:FU12) -> 0 | GC12: =SUM(GA12:GB12) -> 0 | GD12: =FX12+GA12 -> 0 | GE12: =FY12+GB12 -> 0 | GF12: =GD12+GE12 -> 0 | GM12: =SUM(GK12:GL12) -> 0 | GN12: =GH12+GK12 -> 0 | GO12: =GI12+GL12 -> 0 | GP12: =GN12+GO12 -> 0 | GR12: =GN12+GD12+FT12+ES12+EI12+DY12+DO12+CS12+CI12+BT12+BJ12 -> 27 | GS12: =GO12+GE12+FU12+ET12+EJ12+DZ12+DP12+CT12+CJ12+BU12+BK12 -> 0 | GT12: =GH12+FX12+FN12+EM12+EC12+DS12+DI12+CM12+CC12+BN12+BD12 -> 26 | GU12: =GI12+FY12+FO12+EN12+ED12+DT12+DJ12+CN12+CD12+BO12+BE12 -> 0 | GV12: =GK12+GA12+FQ12+EP12+EF12+DV12+DL12+CP12+CF12+BQ12+BG12 -> 1 | GW12: =GL12+GB12+FR12+EQ12+EG12+DW12+DM12+CQ12+CG12+BR12+BH12 -> 0 | GZ12: =GX12+GY12 -> 0 | HC12: =HA12+HB12 -> 0 | HD12: =GX12+HA12 -> 0 | HE12: =GY12+HB12 -> 0 | HF12: =HD12+HE12 -> 0 | HH12: =HD12+GN12+GD12+FT12 -> 0 | HI12: =GO12+GE12+FU12+HE12 -> 0 | HJ12: =GX12+GH12+FX12+FN12 -> 0 | HK12: =GI12+FY12+GY12+FO12 -> 0 | HL12: =GK12+GA12+FQ12+HA12 -> 0 | HM12: =GL12+HB12+GB12+FR12 -> 0 | HO12: =HF12+GP12+GF12+FV12 -> 0 | HP12: =HO12/HN12 -> #DIV/0! | HQ12: =FN12+FX12+GH12+GX12 -> 0 | HR12: =FO12+FY12+GI12+GY12 -> 0 | HS12: =FQ12+GA12+GK12+HA12 -> 0 | HT12: =FR12+GB12+GL12+HB12 -> 0 | HU12: 21 | HV12: 0 | HW12: =HU12+HV12 -> 21 | HX12: 0 | HY12: 0 | HZ12: =HX12+HY12 -> 0 | IA12: =HU12+HX12 -> 21 | IB12: =HV12+HY12 -> 0 | IC12: =IA12+IB12 -> 21 | IJ12: =SUM(IH12:II12) -> 0 | IK12: =SUM(IE12+IH12) -> 0 | IL12: =SUM(IF12+II12) -> 0 | IM12: =SUM(IK12:IL12) -> 0 | IT12: =SUM(IR12:IS12) -> 0 | IU12: =SUM(IO12+IR12) -> 0 | IV12: =SUM(IP12+IS12) -> 0 | IW12: =SUM(IU12:IV12) -> 0 | JB12: 0 | JC12: 0 | JD12: =SUM(JB12:JC12) -> 0 | JE12: =SUM(IY12+JB12) -> 0 | JF12: =SUM(IZ12+JC12) -> 0 | JG12: =SUM(JE12:JF12) -> 0 | JI12: =SUM(IA12+IK12+IU12) -> 21 | JJ12: =SUM(IB12+IL12+IV12) -> 0 | JK12: =SUM(HW12+IG12+IQ12) -> 21 | JL12: =SUM(IJ12+HZ12+IT12) -> 0 | JM12: =SUM(JI12:JJ12) -> 21 | JN12: =JG12+IW12+IM12+IC12 -> 21 | JO12: =JN12/JM12 -> 1 | JS12: 0 | JT12: 0 | JU12: =SUM(JS12:JT12) -> 0 | JV12: =SUM(JP12+JS12) -> 0 | JW12: =SUM(JQ12+JT12) -> 0 | JX12: =SUM(JV12:JW12) -> 0 | JZ12: =JX12+JN12+HO12+FB12 -> 48 | KA12: =SUM(JV12+JE12+IU12+IK12+IA12+HD12+GN12+GD12+FT12+ES12+EI12+DY12+DO12+CS12+CI12+BT12+BJ12+AO12+AE12+U12+K12) -> 48 | KB12: =SUM(JW12+JF12+IV12+IL12+IB12+HE12+GO12+GE12+FU12+ET12+EJ12+DZ12+DP12+CT12+CJ12+BU12+BK12+AP12+AF12+V12+L12) -> 0 | KC12: =SUM(JP12+IY12+IO12+IE12+HU12+GX12+GH12+FX12+FN12+EM12+EC12+DS12+DI12+CM12+CC12+BN12+BD12+AI12+Y12+O12+E12) -> 47 | KD12: =SUM(JQ12+IZ12+IP12+IF12+HV12+GY12+GI12+FY12+FO12+EN12+ED12+DT12+DJ12+CN12+CD12+BO12+BE12+AJ12+Z12+P12+F12) -> 0 | KE12: =SUM(JS12+JB12+IR12+IH12+HX12+HA12+GK12+GA12+FQ12+EP12+EF12+DV12+DL12+CP12+CF12+BQ12+BG12+AL12+AB12+R12+H12) -> 1 | KF12: =SUM(JT12+JC12+IS12+II12+HY12+HB12+GL12+GB12+FR12+EQ12+EG12+DW12+DM12+CQ12+CG12+BR12+BH12+AM12+AC12+S12+I12) -> 0 | KG12: =SUM(KA12:KB12) -> 48 | KH12: 25 | KI12: =KH12-KG12 -> -23 | KJ12: =KG12/KH12 -> 1.92
B13: Training Facilitators for Women and Girls Safe Spaces | C13: Nakivale | D13: 2 | AS13: =AO13+AE13+U13+K13 -> 0 | AT13: =AP13+AF13+V13+L13 -> 0 | AU13: =AK13+AA13+Q13+G13 -> 0 | AV13: =AN13 -> 0 | AX13: =SUM(AQ13+AG13+W13+M13) -> 0 | AZ13: =SUM(E13+O13+Y13+AI13) -> 0 | BA13: =F13+P13+Z13+AJ13 -> 0 | BB13: =H13+R13+AB13+AL13 -> 0 | BC13: =I13+S13+AC13+AM13 -> 0 | BX13: =BN13+BD13+AI13+Y13+O13+E13 -> 0 | BY13: =BO13+BE13+AJ13+Z13+P13+F13 -> 0 | BZ13: =BQ13+BG13+AL13+AB13+R13+H13 -> 0 | CA13: =BR13+BH13+AM13+AC13+S13+I13 -> 0 | CB13: =BX13+BY13+BZ13+CA13 -> 0 | CW13: =SUM(CS13+CI13+BT13+BJ13) -> 0 | CX13: =SUM(CT13+CJ13+BU13+BK13) -> 0 | CY13: =SUM(CU13+CK13+BV13+BL13) -> 0 | CZ13: =SUM(CR13+CH13+BS13+BI13) -> 0 | DB13: =SUM(CW13:CX13) -> 0 | DD13: =BD13+BN13+CC13+CM13 -> 0 | DE13: =BE13+BO13+CD13+CN13 -> 0 | DF13: =BG13+BQ13+CF13+CP13 -> 0 | DG13: =BH13+BR13+CG13+CQ13 -> 0 | DH13: =DB13+AX13 -> 0 | DU13: =SUM(DS13:DT13) -> 0 | DX13: =SUM(DV13:DW13) -> 0 | DY13: =SUM(DS13+DV13) -> 0 | DZ13: =SUM(DT13+DW13) -> 0 | EA13: =SUM(DY13:DZ13) -> 0 | EW13: =SUM(ES13+EI13+DY13+DO13) -> 0 | EX13: =SUM(ET13+EJ13+DZ13+DP13) -> 0 | EY13: =SUM(EO13+EE13+DU13+DK13) -> 0 | EZ13: =SUM(ER13+EH13+DX13+DN13) -> 0 | FB13: =SUM(EW13:EX13) -> 0 | FD13: =DI13+DS13+EC13+EM13+CM13+CC13 -> 0 | FE13: =DJ13+DT13+ED13+EN13+CD13+CN13 -> 0 | FF13: =DL13+DV13+EF13+EP13+CP13+CF13 -> 0 | FG13: =DM13+DW13+EG13+EQ13+CG13+CQ13 -> 0 | FH13: =FD13+FF13 -> 0 | FI13: =FE13+FG13 -> 0 | FJ13: =FH13+FI13 -> 0 | FK13: =EW13+CW13+AS13 -> 0 | FL13: =EX13+CX13+AT13 -> 0 | FM13: =FK13+FL13 -> 0 | GD13: =FX13+GA13 -> 0 | GE13: =FY13+GB13 -> 0 | GF13: =GD13+GE13 -> 0 | GN13: =GH13+GK13 -> 0 | GO13: =GI13+GL13 -> 0 | GP13: =GN13+GO13 -> 0 | GR13: =GN13+GD13+FT13+ES13+EI13+DY13+DO13+CS13+CI13+BT13+BJ13 -> 0 | GS13: =GO13+GE13+FU13+ET13+EJ13+DZ13+DP13+CT13+CJ13+BU13+BK13 -> 0 | GT13: =GH13+FX13+FN13+EM13+EC13+DS13+DI13+CM13+CC13+BN13+BD13 -> 0 | GU13: =GI13+FY13+FO13+EN13+ED13+DT13+DJ13+CN13+CD13+BO13+BE13 -> 0 | GV13: =GK13+GA13+FQ13+EP13+EF13+DV13+DL13+CP13+CF13+BQ13+BG13 -> 0 | GW13: =GL13+GB13+FR13+EQ13+EG13+DW13+DM13+CQ13+CG13+BR13+BH13 -> 0 | GZ13: =GX13+GY13 -> 0 | HC13: =HA13+HB13 -> 0 | HD13: =GX13+HA13 -> 0 | HE13: =GY13+HB13 -> 0 | HF13: =HD13+HE13 -> 0 | HH13: =HD13+GN13+GD13+FT13 -> 0 | HI13: =GO13+GE13+FU13+HE13 -> 0 | HJ13: =GX13+GH13+FX13+FN13 -> 0 | HK13: =GI13+FY13+GY13+FO13 -> 0 | HL13: =GK13+GA13+FQ13+HA13 -> 0 | HM13: =GL13+HB13+GB13+FR13 -> 0 | HO13: =HF13+GP13+GF13+FV13 -> 0 | HQ13: =FN13+FX13+GH13+GX13 -> 0 | HR13: =FO13+FY13+GI13+GY13 -> 0 | HS13: =FQ13+GA13+GK13+HA13 -> 0 | HT13: =FR13+GB13+GL13+HB13 -> 0 | HW13: =HU13+HV13 -> 0 | HZ13: =HX13+HY13 -> 0 | IA13: =HU13+HX13 -> 0 | IB13: =HV13+HY13 -> 0 | IC13: =IA13+IB13 -> 0 | JN13: =JG13+IW13+IM13+IC13 -> 0 | JZ13: =JX13+JN13+HO13+FB13 -> 0 | KA13: =SUM(JV13+JE13+IU13+IK13+IA13+HD13+GN13+GD13+FT13+ES13+EI13+DY13+DO13+CS13+CI13+BT13+BJ13+AO13+AE13+U13+K13) -> 0 | KB13: =SUM(JW13+JF13+IV13+IL13+IB13+HE13+GO13+GE13+FU13+ET13+EJ13+DZ13+DP13+CT13+CJ13+BU13+BK13+AP13+AF13+V13+L13) -> 0 | KC13: =SUM(JP13+IY13+IO13+IE13+HU13+GX13+GH13+FX13+FN13+EM13+EC13+DS13+DI13+CM13+CC13+BN13+BD13+AI13+Y13+O13+E13) -> 0 | KD13: =SUM(JQ13+IZ13+IP13+IF13+HV13+GY13+GI13+FY13+FO13+EN13+ED13+DT13+DJ13+CN13+CD13+BO13+BE13+AJ13+Z13+P13+F13) -> 0 | KE13: =SUM(JS13+JB13+IR13+IH13+HX13+HA13+GK13+GA13+FQ13+EP13+EF13+DV13+DL13+CP13+CF13+BQ13+BG13+AL13+AB13+R13+H13) -> 0 | KF13: =SUM(JT13+JC13+IS13+II13+HY13+HB13+GL13+GB13+FR13+EQ13+EG13+DW13+DM13+CQ13+CG13+BR13+BH13+AM13+AC13+S13+I13) -> 0 | KG13: =SUM(KA13:KB13) -> 0 | KH13: 2 | KI13: =KH13-KG13 -> 2 | KJ13: =KG13/KH13 -> 0
