Workbook

Sheet a. Problem Tree Documentation.
A1: Instructions: The easiest way to insert a final draft of the Problem Tree analysis into the Project Design Workbook is to use the “Snipping Tool” which is a Microsoft tool found in the Start Menu: All Programs – Accessories – Snipping Tool. Select and copy the whole graphic and paste it into the Project Design Workbook in the Problem Analysis Documentation tab. The Snipping Tool can be used to copy and paste from any electronic medium, including websites, Microsoft Office applications, etc.
A2: KEY: Any method or program can be used to document the results of the Problem Analysis in the Project Design Workbook, including a photo of the document the group uses to work through this analysis. What is important is that the results are documented and can be clearly read.
A3: Below is an example of a Word template pasted in the tab using the Snipping Tool. Simply delete this example and paste your finalized Problem Analysis results when it is completed.
G4: LWR PROBLEM TREE SAMPLE MODEL
C6: Effect 1: Food Insecurity | F6: Effect 2: Poor Household income | I6: Effect 3: Poor Nutrition | L6: Effect 4: Poor Health
C8: Problem Statement:Low income, self reliance and and livelihood opportunities for South Sudan refugees and their host communities in and around palabek settlement.
E10: Cause 1: There is poor productivity and low income from agriculture for South Sudanese refugees and host communities | H10: Cause 2: South Sudan vulnerable refugees have poor living conditions
E13: Cause 1.a: South Sudan refugees and host communities have poor access to agricultural extension services | H13: Cause 2.a: South Sudan vulnerable refugees have limited access to resources.
E16: Cause 1.b: South Sudan and host communities have limited access to agricultural inputs | H16: Cause 2.b: South Sudan refugee children have limited access to material resources.
E19: Cause 1.c: South Sudan refugees and host communities have poor knowledge on recommended agronomic practices.

Sheet b. Problems to Objectives
A1: Explanation | B1: The PROBLEM/CAUSE column: Enter the problems and causes from the Problem Analysis. Remember, the problems and causes are the reality currently experienced in the target area. These are therefore expressed as the negative condition. For example, "Poor agricultural productivity in the priority action zone." | C1: The EVIDENCE FOR PROBLEM/CAUSE W/CITATION column is a way to document the source of the evidence for each problem or cause. It helps ensure that the problems and causes identified in the project design are based on actual or observed situations. It is a way to document what is found in the Needs Assessment but can also come from peer agency needs assessments, government reports, agency reports or another published document. The document or source of the evidence for each problem/cause should be written in parenthesis after the evidence. For example, if the Problem is "poor agricultural productivity in the priority action zone," then the evidence with citation could be “Agricultural output in the PAZ has decreased by 25% from 2011-2013 (Needs assessment section 2.1).” The citation helps document key information and can also assist in setting indicators or beneficiary targets. | E1: The OBJECTIVE STATEMENT column is where the project's objectives are documented. Having this column on the same page as the PROBLEM/CAUSE helps ensure that the proposed objective responds to the problems/causes identified during the assessment stage. The objectives statements are the opposite of negative condition identified in the Problem Analysis. They are written as the positive condition and as if the result has already been achieved. The Objective Analysis Tool Summary, as well as the guidance in the sections related to the objective analysis in the IFRC Project Planning Guidance, can assist in selecting the most appropriate objectives for the context of the project. The Results Framework can then be used to verify the logic between the selected Goal, Outcomes and Outputs.
A2: Project Title: | B2: REselience SUpport Leading To Sustainable Livelihoods for South Sudanese Refugees (RESULTS Livelihoods) Project
A3: # | B3: PROBLEM/CAUSE | C3: EVIDENCE FOR PROBLEM-CAUSE W/ CITATION | D3: # | E3: OBJECTIVE STATEMENT
A4: Problem 1 | B4: Targeted South Sudan refugees and their host communities do not optimise income and livelihood opportunities | D4: GOAL: | E4: Targeted South Sudan refugees and their host communities optimize income, self reliance and livelihood opportunities
A5: Cause 1 | B5: Targeted South Sudan refugees and their host communities have poor productivity and low income from agriculture | D5: Outcome 1 | E5: Targeted South Sudan refugees and their host communities have improved productivity and increased income generated from agriculture
A6: Cause 1.1 | B6: Targeted South Sudan refugees and their host communities have poor access to agricultural extension services | D6: Output 1.1 | E6: Targeted South Sudan Refugees and their host communities have access to agricultural extension services
A7: Cause 1.2 | B7: Targeted South Sudan refugees and their host communities have limited access to agricultural inputs | D7: Output 1.2 | E7: Targeted South Sudan Refugees and their host communities have access to agricultural inputs
A8: Cause 1.3 | B8: Targeted South Sudan refugees and their host communities have poor knowledge on recommended agronomic practices | D8: Output 1.3 | E8: Targeted South Sudan Refugees and their host communities practice climate smart agriculture
A9: Cause 2 | B9: Targeted South Sudn vulnerable refugees have poor living conditions | D9: Outcome 2 | E9: Targeted South Sudan vulnerable refugees have improved living conditions
A10: Cause 2.1 | B10: Targeted South Sudan vulverable refugees have limited access to resources | D10: Output 2.1 | E10: Targeted South Sudan vulnerable refugees have access to resources (mission quilts and personal care kits)
A11: Cause 2.2 | B11: Targeted South Sudan refugees children have limited access to material resources | D11: Output 2.2 | E11: Targeted South Sudan refugee children have access to material resources (baby care kits)
A12: Cause 3 | D12: Outcome 3
A13: Cause 3.1 | D13: Output 3.1
A14: Cause 4 | D14: Outcome 4
A15: Cause 4.1 | D15: Output 4.1
A16: Cause 5 | D16: Outcome 5
A17: Cause 5.1 | D17: Output 5.1

Sheet c. Results Framework
A1: The following 3 templates (Results Framework, Logframe, Work Plan) are designed to be used together and some cells are linked. When you enter information into the Results Framework, it automatically fills in details in the Logical Framework and Work Plan. This ensures that the objectives statements are consistent throughout the document. If edits are made to the objective statements, only make changes in the Results Framework. Because the Results Framework, LogFrame and WorkPlan are linked, it is very important to NOT modify the formulas in the objective statement columns of the Evidence for Cause, Logframe and Work Plan tabs. If you have any questions about modifying these templates, please contact the M&E Unit for technical support.
A2: Project Title | B2: ='b. Problems to Objectives'!B2:E2 -> REselience SUpport Leading To Sustainable Livelihoods for South Sudanese Refugees (RESULTS Livelihoods) Project
A4: GOAL: | B4: ='b. Problems to Objectives'!E4 -> Targeted South Sudan refugees and their host communities optimize income, self reliance and livelihood opportunities
A6: Outcome | C6: =A6 -> Outcome | E6: =C6 -> Outcome | G6: =E6 -> Outcome | I6: =G6 -> Outcome
A7: 1 | C7: =A7+1 -> 2 | E7: =C7+1 -> 3 | G7: =E7+1 -> 4 | I7: =G7+1 -> 5
A8: ='b. Problems to Objectives'!E5 -> Targeted South Sudan refugees and their host communities have improved productivity and increased income generated from agriculture | C8: ='b. Problems to Objectives'!E9 -> Targeted South Sudan vulnerable refugees have improved living conditions | E8: ='b. Problems to Objectives'!E12 -> 0 | G8: ='b. Problems to Objectives'!E14 -> 0
B9: Output | D9: =B9 -> Output | F9: =D9 -> Output | H9: =F9 -> Output | J9: =H9 -> Output
B10: =A7+0.1 -> 1.1 | D10: =C7+0.1 -> 2.1 | F10: =E7+0.1 -> 3.1 | H10: =G7+0.1 -> 4.1 | J10: =I7+0.1 -> 5.1
B11: ='b. Problems to Objectives'!E6 -> Targeted South Sudan Refugees and their host communities have access to agricultural extension services | D11: ='b. Problems to Objectives'!E10 -> Targeted South Sudan vulnerable refugees have access to resources (mission quilts and personal care kits) | F11: ='b. Problems to Objectives'!E13 -> 0 | H11: ='b. Problems to Objectives'!E15 -> 0 | J11: ='b. Problems to Objectives'!E17 -> 0
B12: =B10+0.1 -> 1.2 | D12: =D10+0.1 -> 2.2 | F12: =F10+0.1 -> 3.2 | H12: =H10+0.1 -> 4.2 | J12: =J10+0.1 -> 5.2
B13: ='b. Problems to Objectives'!E7 -> Targeted South Sudan Refugees and their host communities have access to agricultural inputs | D13: ='b. Problems to Objectives'!E11 -> Targeted South Sudan refugee children have access to material resources (baby care kits)
B14: =B12+0.1 -> 1.3 | D14: =D12+0.1 -> 2.3 | H14: =H12+0.1 -> 4.3 | J14: =J12+0.1 -> 5.3
B15: ='b. Problems to Objectives'!E8 -> Targeted South Sudan Refugees and their host communities practice climate smart agriculture
B16: =B14+0.1 -> 1.4 | D16: =D14+0.1 -> 2.4 | F16: =F14+0.1 -> 0.1 | H16: =H14+0.1 -> 4.4 | J16: =J14+0.1 -> 5.4
B18: =B16+0.1 -> 1.5 | D18: =D16+0.1 -> 2.5 | H18: =H16+0.1 -> 4.5 | J18: =J16+0.1 -> 5.5

Sheet d. LogFrame
A1: ='c. Results Framework'!A2 -> Project Title | E1: ='c. Results Framework'!B2 -> REselience SUpport Leading To Sustainable Livelihoods for South Sudanese Refugees (RESULTS Livelihoods) Project
C2: PROBLEM/CAUSE | D2: EVIDENCE OF PROBLEM-CAUSE WITH CITATION | E2: OBJECTIVE STATEMENT | F2: OBJECTIVELY VERIFIABLE INDICATOR | G2: MEANS OF VERIFICATION | H2: RISK AND ASSUMPTION
A3: ='c. Results Framework'!A4 -> GOAL: | C3: ='b. Problems to Objectives'!B4 -> Targeted South Sudan refugees and their host communities do not optimise income and livelihood opportunities | D3: ='b. Problems to Objectives'!C4 -> 0 | E3: ='c. Results Framework'!B4 -> Targeted South Sudan refugees and their host communities optimize income, self reliance and livelihood opportunities
A4: ='c. Results Framework'!A6 -> Outcome | B4: ='c. Results Framework'!A7 -> 1 | C4: ='b. Problems to Objectives'!B5 -> Targeted South Sudan refugees and their host communities have poor productivity and low income from agriculture | D4: ='b. Problems to Objectives'!C5 -> 0 | E4: ='c. Results Framework'!A8 -> Targeted South Sudan refugees and their host communities have improved productivity and increased income generated from agriculture | F4: 1a 80% of Refugee and host communities HHs report increased food production by Sept 2018 | G4: Presence of backyard gardens in target refugee house holds | H4: Refugees and host communities embrace the services provided by the project
A5: ='c. Results Framework'!B9 -> Output | B5: ='c. Results Framework'!B10 -> 1.1 | C5: ='b. Problems to Objectives'!B6 -> Targeted South Sudan refugees and their host communities have poor access to agricultural extension services | D5: ='b. Problems to Objectives'!C6 -> 0 | E5: ='c. Results Framework'!B11 -> Targeted South Sudan Refugees and their host communities have access to agricultural extension services | F5: 1.1a 40 women refugee volunteers are identified and selected to support extension service provision 1.1b 1800 refugees are receiving extension services from refugee volunteer farmers | G5: Presence of Volunteer Refugee farmers that have been trained in good agronomic practices | H5: Refugees and host communities are interested in getting extension support
A6: Activity | B6: 1.1.A. | E6: Identify volunteer youth farmers from Refugee households and host community
A7: Activity | B7: 1.1.B. | E7: Conduct a TOT for the Refugee Women Volunteers in Good agronomic practices
A8: Activity | B8: 1.1.C. | E8: Conduct regular field visits to host community farmers and Refugees HHs
A9: =A5 -> Output | B9: ='c. Results Framework'!B12 -> 1.2 | C9: ='b. Problems to Objectives'!B7 -> Targeted South Sudan refugees and their host communities have limited access to agricultural inputs | D9: ='b. Problems to Objectives'!C7 -> 0 | E9: ='c. Results Framework'!B13 -> Targeted South Sudan Refugees and their host communities have access to agricultural inputs | F9: 1.2.a 64 farmer groups of both refugees and host communities are formed 1.2b 1920 refugees and host community HHs receive agricultural seeds (OLSP, beans and amaranth) | G9: Presence of distribution records | H9: Presence of quality seed inputs and suppliers
A10: Activity | B10: 1.2.A. | E10: Formation of farmer groups at refugee and host community levels
A11: Activity | B11: 1.2.B. | E11: Provide Agricultural seeds to identified Refugee and host community HHs
A12: Activity | B12: 1.2.C. | E12: Conduct quarterly review meetings to review project progress
A13: =A9 -> Output | B13: ='c. Results Framework'!B14 -> 1.3 | C13: ='b. Problems to Objectives'!B8 -> Targeted South Sudan refugees and their host communities have poor knowledge on recommended agronomic practices | D13: ='b. Problems to Objectives'!C8 -> 0 | E13: ='c. Results Framework'!B15 -> Targeted South Sudan Refugees and their host communities practice climate smart agriculture | F13: 1.3.a 1920 refugee households are applying good agronomic practices in their gardens | G13: Presence of backyard gardens at target refugee and host community house holds | H13: Refugges and host communites are willing to learn
A14: Activity | B14: 1.3.A. | E14: Setup RHHs and host community backyard gardens
A15: Activity | B15: 1.3.B. | E15: Provide technical backstoping to model farmers
A16: Activity | B16: 1.3.C.
A17: =A4 -> Outcome | B17: ='c. Results Framework'!C7 -> 2 | C17: ='b. Problems to Objectives'!B9 -> Targeted South Sudn vulnerable refugees have poor living conditions | D17: ='b. Problems to Objectives'!C9 -> 0 | E17: ='c. Results Framework'!C8 -> Targeted South Sudan vulnerable refugees have improved living conditions | F17: 2a 100% of vulnerable refugee women and children are properly selected and documented | G17: Presence of records of distribution lists for both the mothers and babies | H17: Refugees and host communities are interested to learn how to use the items provided
A18: ='c. Results Framework'!D9 -> Output | B18: ='c. Results Framework'!D10 -> 2.1 | C18: ='b. Problems to Objectives'!B10 -> Targeted South Sudan vulverable refugees have limited access to resources | D18: ='b. Problems to Objectives'!C10 -> 0 | E18: ='c. Results Framework'!D11 -> Targeted South Sudan vulnerable refugees have access to resources (mission quilts and personal care kits) | F18: 2.1.a 3000 vulnerable refugee women receive material resouces of mission quilts and personal care kits | G18: Presence of records of distribution lists for mission quilts and personal care kits | H18: Refugees and host communities are interested to learn how to use the items provided
A19: Activity | B19: 2.1.A. | E19: Selection and documetnation of the most in need refugees
A20: Activity | B20: 2.1.B. | E20: Distribution of Quilts and personal Care kits
A21: Activity | B21: 2.1.C.
A22: =A18 -> Output | B22: ='c. Results Framework'!D12 -> 2.2 | C22: ='b. Problems to Objectives'!B11 -> Targeted South Sudan refugees children have limited access to material resources | D22: ='b. Problems to Objectives'!C11 -> 0 | E22: ='c. Results Framework'!D13 -> Targeted South Sudan refugee children have access to material resources (baby care kits) | F22: 2.2.a 2,682 babies receive material resources of baby care kits | G22: Presence of records of distribution lists for baby care kits | H22: Refugees and host communities are interested to learn how to use the items provided
A23: Activity | B23: 2.2.A. | E23: Selection and documetnation refugee Women with new borns
A24: Activity | B24: 2.2.B. | E24: Distribution of baby care Kits to 2,682 babies
A25: Activity | B25: 2.2.C.
A26: =A17 -> Outcome | B26: ='c. Results Framework'!E7 -> 3 | C26: ='b. Problems to Objectives'!B12 -> 0 | D26: ='b. Problems to Objectives'!C12 -> 0 | E26: ='c. Results Framework'!E8 -> 0
A27: ='c. Results Framework'!F9 -> Output | B27: ='c. Results Framework'!F10 -> 3.1 | C27: ='b. Problems to Objectives'!B13 -> 0 | D27: ='b. Problems to Objectives'!C13 -> 0 | E27: ='c. Results Framework'!F11 -> 0
A28: Activity | B28: 3.1.A.
A29: Activity | B29: 3.1.B.
A30: =A26 -> Outcome | B30: ='c. Results Framework'!G7 -> 4 | C30: ='b. Problems to Objectives'!B14 -> 0 | D30: ='b. Problems to Objectives'!C14 -> 0 | E30: ='c. Results Framework'!G8 -> 0
A31: ='c. Results Framework'!H9 -> Output | B31: ='c. Results Framework'!H10 -> 4.1 | C31: ='b. Problems to Objectives'!B15 -> 0 | D31: ='b. Problems to Objectives'!C15 -> 0 | E31: ='c. Results Framework'!H11 -> 0
A32: Activity | B32: 4.1.A.
A33: Activity | B33: 4.1.B.
A34: =A30 -> Outcome | B34: ='c. Results Framework'!I7 -> 5 | C34: ='b. Problems to Objectives'!B16 -> 0 | D34: ='b. Problems to Objectives'!C16 -> 0 | E34: ='c. Results Framework'!I8 -> 0
A35: ='c. Results Framework'!J9 -> Output | B35: ='c. Results Framework'!J10 -> 5.1 | C35: ='b. Problems to Objectives'!B17 -> 0 | D35: ='b. Problems to Objectives'!C17 -> 0 | E35: ='c. Results Framework'!J11 -> 0
A36: Activity | B36: 5.1.A.
A37: Activity | B37: 5.1.B.

Sheet Detail M&E Plan Instructions
A1: LWR Detailed M&E Plan Instructions
A2: 1. Complete the M&E Matrix: It can be developed within the tab or within a Word document and transferred to the M&E Matrix tab.
A3: a. For detailed instructions on completing the content of the M&E Matrix, please refer to tab c. M&E Matrix Cheat Sheet.
A4: b. Enter the objective statements and indicators ONLY in the M&E Matrix. They are automatically linked to the Indicator Tracking Table (ITT) and the Activity Tracking Table (ATT).
A5: 2. Baseline Table:
A6: a. Fill in the Baseline Table after or as the baseline data is collected either by a consultant or the project team.
A7: 3. Complete the Indicator Tracking Table: See tab i. for further instructions on using the ITT.
A8: a. Fill in the Project Name and the Project Year (PY) for the ITT. The blank version of this workbook contains linked ITT and ATT tables for up to a three year project.
A9: b. Fill in the baseline values for each indicator including the date it was collected and the unit of measurement. If the baseline values do not come from a consolidated baseline survey, note in the status column where the values are archived (the document, file, government database, etc). The baseline values are automatically populated in the Year 2 and Year 3 ITTs in the blank workbook.
A10: 4. Set indicator targets:
A11: a. Indicator targets should be set for each indicator based upon the details outlined in the project proposal taking into consideration timelines, number of staff, and budget. Start with Life of Project (LOP) targets, then annual targets, then quarterly targets. Targets should be based on the project’s work plan/detailed implementation plan.
A12: i. All targets and actuals should be cumulative. This means that targets and actuals recorded for each quarter reflect what has been targeted or achieved to date. If a given indicator cannot be recorded in a cumulative manner for some reason, include a note in the status column.
... A27: d. For each reporting period, update the status of the activity in column W. It should be updated with "Not yet started," In progress," or "Completed." If it is completed, list the date completed.

Sheet M&E Matrix Description
A1: TOOL SUMMARY: M&E MATRIX INSTRUCTIONS
A2: Purpose | B2: The purpose of this tool is to guide staff to complete each column of the M&E Matrix.
B3: · The M&E Matrix is a critical tool for planning and managing data collection, analysis, and use. It expands on the Logframe to identify key information requirements for each indicator and summarizes the key M&E tasks for the project.
B4: o It helps staff determine if a proposed indicator can effectively measure the result to which it is linked.
B5: o It helps staff determine if the proposed indicators can feasibly be collected given time and resource constraints.
A6: Information Sources | B6: Information the project team should have before starting the M&E Matrix:
B7: · Logframe
B8: · Project Proposal (Initial M&E Plan)
B9: Guidance for M&E Matrix:
B10: · CRS SMILER Guide
A11: Who | B11: This tool is a reference that can be used as a reference for by any staff working to complete the M&E Matrix
A12: When | B12: Given that the M&E Matrix helps define the scope (cost, time) of the project’s monitoring system, it is recommended that the Indicator Definition, Frequency/Schedule, and Responsible Person columns be completed before finalizing the project proposal.
B13: The remaining columns of the M&E Matrix should be filled out as the information becomes available, but must be finalized within the following timeframes:
B14: · Projects 1 year or less: complete a detailed M&E plan within 60 days of the project approval
B15: · Projects with a duration of 1-3 years: complete a detailed M&E plan within 90 days of the project approval
B16: · Projects with a duration of 3-5 years: complete a detailed M&E plan within 120 days of project approval
A17: Requirements | B17: REQUIREMENTS:
B18: · This M&E Matrix should be used for all LWR projects.
B19: · The M&E Matrix is a living document and should be updated based upon relevant project adjustments
B20: o If the M&E Matrix is changed report the changes, the reason, and how it affects other aspects of the M&E and project implementation plan
B21: o If changes are made to the plan, ensure that HQ, the country office, and the partner have the updated version
B22: RECOMMENDATIONS:
B23: · Ideally, the M&E Matrix will be finalized during a joint project planning meeting (project kick-off meeting) with participation from both key partner and LWR staff.
B24: SMART Criteria:
B25: · SMART criteria are: Specific, Measurable, Attainable, Relevant, and Timebound.
B26: · It is recommended that objective statements in the Logframe are NOT written using SMART criteria.
B27: o Nevertheless, SMART objective statements can sometimes be used effectively within project proposals to show all the details of the expected result in one statement.
B28: · SMART criteria should be applied to indicators, not objective statements. (reference p. 37 of IFRC Project Planning Guidance Manual for further information on SMART criteria).
B29: · Follow the instructions and examples for writing indicators found in the Logframe Cheat Sheet.
B30: · As presented in the Logframe, each indicator may not meet all the SMART criteria, but once the M&E Matrix is fully developed the indicators should be SMART.
A31: Tips | B31: · The M&E Matrix should be completed by those who will be using it. This allows the project team to crosscheck the Logframe and indicators before project implementation (ensuring they are sensitive to field realities and team capacities). Team involvement is essential because the M&E Matrix requires their detailed knowledge of the project context, and their involvement reinforces their understanding of what data they are to collect and how they will collect them.
B32: · Keep the M&E Matrix plan appropriate for the scale and timeframe of the project. Remember, it should be ‘good enough’.
B33: · Double check that your indicators can be measured in a realistic manner. Balance qualitative and quantitative data to measure indicators.
B34: · Make sure to be clear who within the project team is responsible for “owning the M&E Matrix.” This includes ensuring it is thoroughly completed, that all relevant project stakeholders understand it and have copies of it, that any changes made are fully incorporated and shared, and to regularly monitor and manage that all outlined tasks are being completed. The same person should also be responsible for managing the Indicator Tracking Table and the Activity Tracking Table.
B35: · The M&E Matrix is nearly identical to USAID’s Performance Monitoring Plan. The instructions for the M&E Matrix can be applied to complete USAID’s PMP.
A36: How to Address Gender Issues | B36: · Sex-disaggregate data of all indicators for which people are the unit of measure.
B37: · Include qualitative and quantitative indicators .

Sheet M&E Matrix Cheat Sheet
A1: M&E Matrix Cheat Sheet [1]
A2: PERFORMANCE INDICATORS | D2: DATA GATHERING | H2: ANALYSIS, USE, REPORTING
A3: Indicator | B3: Indicator Definition | C3: Unit of Measurement | D3: Method | E3: Means of Verification (Data Source/Tools) | F3: Frequency & Schedule | G3: Responsible Person | H3: Data Analysis | I3: Information Use/Audience | J3: Reporting
A4: - Indicators are taken from the logframe. When transferring them, check to ensure they are SMART (specific, measureable, achievable, relevant, and time-bound). - Often, the indicator may need to be revised according to field realities. If this is the case, be sure any revisions are approved by LWR and/or the donor. - If indicators are updated here, ensure the logframe is also updated. | B4: - Each indicator needs a detailed definition of its key terms, including an explanation of specific aspects that will be measured (such as who, what, and where the indicator applies). - Define subjective words as necessary, such as “appropriate,” “successful,” “sustainable,” “sufficient,” “capacity,” etc. - The definition should explain precisely how the indicator will be calculated, such as the numerator and denominator of a percent measure. - This column should also note if the indicator is to be disaggregated by sex, age, ethnicity, or some other variable. | C4: -Each indicator must have a clear unit of measure. | D4: -This column can be used to outline if the indicator will be collected during the baseline, during monitoring, and/or at the end of the project. Each of these require specific methods by which data will be collected during that period. These can include approaches such as use of secondary data, regular monitoring, baseline or endline surveys, PRA, focus group discussions, etc. -The method should match the Means of Verification. For example, if the method is ‘regular monitoring,’ the means of verification should be some type of report regularly produced by project staff. | E4: - This column identifies sources of information. - If multiple sources are listed, it must be clear how the information in the various sources will come together to make one aggregated data point for the indicator that can be entered into the ITT. - This column should also indicate whether data collection tools (questionnaires, checklists) are pre-existing or will need to be developed. - The logframe column on “Means of Verification” may list only one source (field agent report). The M&E plan requires much more detail, since the M&E system much include all responsbilities and related data collection templates and timeframes. | F4: - This column states the frequency for each indicator (monthly, quarterly, annually) as well as the scheduled (day/month/year). - The frequency and schedule listed must match the targets set in the Indicator Tracking Table. - When planning for data collection timing, it is important to consider factors such as planting and harvest periods, seasonal variations, school schedules, holidays, and religious observances (i.e. Ramadan). | G4: - This column lists the people responsible and accountable for the data collection and analysis, i.e., community volunteers, field staff, project managers, local partner/s, and external consultants. - In addition to specific people’s names, use the position title to ensure clarity in case of personnel changes. - This column is useful to budget for M&E staff and planning for their capacity building. | H4: -This column should be used by the project team for whatever reminders or support are deemed practical. It describes the process for compiling and analyzing the data. This process gauges if the indicator has been met. - For example, survey data usually requires statistical analysis, while qualitative data may be reviewed by research staff or community members. - Include any questions that the project team may want to ask to better understand the data once it is compiled. | I4: - This column identifies the intended audience and use of the information. - For example, the findings could be used for monitoring project implementation, evaluating the interventions, planning future project work, or reporting to policy makers or donors. - Defining how you will use the information helps eliminate unnecessary indicators or analysis. The data should be linked clearly to decision making and/or accountability. - Reduce the quantity and frequency of data collection if the tabulation and analysis cannot be done in time for decision-making or communications and reporting. | J4: - It is important to identify in which reports each indicator data will appear. Communication and reporting mapping will assist in identifying where each indicator is reported. - This column should also state ways that the findings will be formatted (tables, graphs, maps, histograms, narrative reports). This will help to ensure that only the most relevant data and information is reported to each stakeholder, and will increase the likelihood of feedback on reported information.
A6: [1] M&E Plan Matrix template was derived from IFRC’s M&E Plan Template (April 6, 2011): http://ifrc.org/en/who-we-are/performance-and-accountability/monitoring-and-evaluation/, and CRS’ ProPak. The content for the instructions were borrowed primarily from IFRC’s M&E Plan Template (April 6, 2011) with additional content borrowed from CRS’ M&E in Emergencies, DESIGN: How to develop an M&E plan in an emergency project M&E Plan Template, Appendix 3, p. 54.

Sheet M&E Matrix Example 
A1: Project Name: | D1: Project Location: | H1: Project Year:
A2: Identifier | D2: Partner: | H2: Project Start Date:
A3: Project Sector(s): | H3: Project End Date:
A4: PERFORMANCE INDICATORS | D4: DATA GATHERING | H4: ANALYSIS, USE, REPORTING
A5: Indicator | B5: Indicator Definition | C5: Unit of Measurement | D5: Method | E5: Means of Verification | F5: Frequency and Schedule | G5: Reponsible person/ team | H5: Data Analysis | I5: Information Use/Audience | J5: Reporting
A6: GOAL: Communities living along Nepal- India boarder have a better quality of life as a result of being more resilient to flooding
A8: OUTCOME 1: Households living along the Nepal-India border have more robust livelihoods
A9: Indicator 1.a: % increase in household savings. | B9: % increase calculation: ((new period savings value - prior period savings value)/prior period savings value))*100 HH calculation: (savings increase of men + savings increase of women)/# members in HH with savings ITT Calculation: sum of all HH savings increase/total # HH Disaggregated by savings held by men and women within the household. | C9: Unit (s): Men and Women (in HH with savings) Household | D9: Baseline: 1. Household survey Monitoring: 2. Census Endline: N/A | E9: 1. Consultant database/Baseline Report 2.1. ITT 2.2. Director database 2.3. Consolidated savings group records 2.4 Savings group records | F9: 1. Beginning of project (Oct. 31, 2016) 2.1 Annually (Jan. 30) 2.2 Annually (Jan. 15) 2.3. Annually (Jan. 2) 2.4. Ongoing | G9: 1. Consultant 2.1. Project Director 2.2. Data entry officer 2.3. Field officer 2.4. Savings group record keeper | H9: Are men and women's savings rate different? If so, why? How much of the household savings is being used for livelihood activities? What is the minimum rate of savings that creates a robust livelihood? | I9: Project management team to determine if savings rates are increasing sufficiently to create more robust livelihoods. Savings group leaders to determine which members are more successful than others and how they can improve savings rates overall. | J9: Quarterly LWR progress reports.
A10: OUTPUT 1.1: Target communities have improved access to financial services
A11: Indicator 1.1.a: # of saving and credit groups/cooperatives formed and strengthened | B11: Calculation: Count number of formal/informal gropus involved in saving and Credits, Savings and Credit Group/Cooperative: Regulating fund mobilization at the community level Formed: created Strengthened: trained on purpose, norms | C11: Unit: Number of Saving and Credits groups | D11: Ongoing monitoring; Cooperative/self-help group meetings Partner responsible for Baseline data | E11: 1. ITT 2. Project Coordinator database 3. Social Mobilizer report | F11: 1. Quarterly 2. Quarterly 3. Monthly | G11: 1. Program Manager 2. Project Coordinator 3. Social Mobilizer | H11: Is the number of groups increasing over time? Are the groups getting stronger and/or improving their ability to provide service? | I11: Partners | J11: Quarterly

Sheet M&E Matrix
A1: “REAP PROJECT” M&E Matrix
A2: Project Name: | B2: RESULTS Livelihoods | D2: Project Location: | E2: Lamwo District | G2: Project Year: | I2: January 2018 -September 2018
A3: Identifier: | B3: 18-2210-1 | D3: Partner: | E3: African Women and Youth Action for Development | H3: Project Start Date: | I3: 1.01.2018
A4: Project Sector(s): | B4: Agriculture | H4: Project End Date: | I4: 30.09.2018
A5: PERFORMANCE INDICATORS | D5: DATA GATHERING | H5: ANALYSIS, USE, REPORTING
A6: Indicator | B6: Indicator Definition | C6: Unit of Measurement | D6: Method | E6: Mean of Verification | F6: Frequency and Schedule | G6: Reponsible person/ team | H6: Data Analysis | I6: Information Use/Audience | J6: Reporting Deadline
A7: GOAL: Increased household self-reliance and resilience among refugees and host community members in Palabek and Kyaka II refugee settlements.
A9: Outcome 1. Increased household food security and incomes among refugees and host communities
A10: Indicator 1.A. 1200 refugees and host communities achieve atleast 30% increase in household food production. | B10: 30% increase in food production calculation: ((new period amount of food produced - prior period amount of food produced)/prior period amount of food produced))*100 ITT Calculation: Count all refugees and host communities who achieved 30% + food production a year. | C10: Unit (s): Men and Women (engaged in own food production) Household | D10: Baseline: 1. Household survey Monitoring: 2. Census Endline: 3. Household survey | E10: 1. Consultant database/Endline Report 2.1. ITT 2.2. Consolidated group production records 2.3. Household group records | F10: 1. Beginning of year 2 (Oct. 31, 2018) 2. End of qourter 1 (31st December) 2. End of Quarter 2 (March 31st) 3. End of Quarter 3 (June 30th) 4. End of year (Sept 30th) 5. Endline Survey 6. Ongoing | G10: 1. Consultant 2.1. Project Manager 2.2. Project Ext officer 2.3. Field officer 2.4. Household record keeper | H10: Is own food production reducing dependence on food aid? If not, why? Is own food production contributing to increase in consumption diversity? Between male and female headed households, which are more food secure? | I10: 1. United Nations High Commission for Refugees (UNHCR) 2. Office of the Prime Minister (OPM) 3. Lamwo & Kyegegwa District Local Governments. 4. LWR Country Office & HQ. | J10: Quarterly LWR progress reports.
A11: Indicator 1.B. 800 refugees and host communities acquire atleast one productive household asset and one non-productive asset. | B11: ITT Calculation: 1. Count number of women who bought a productive asset within project period. 2. Count number of women who bought a productive asset within project period. 3. Add the number of women and men who bought a productive asset within project period. A productive asset may include: Farm tools, business equipment, livestock, bodaboda, truck, land, house, etc. | C11: Unit (s): Men and Women (in HH with Assets) Household | D11: Baseline: 1. Household survey Monitoring: 2. Census Endline: 3. Household survey | E11: 1. Consultant database/Endline Report 2.1. ITT 2.3.Household asset purchase records | F11: 1. Beginning of year 2 (Oct. 31, 2018) 2. End of qourter 1 (31st December) 2. End of Quarter 2 (March 31st) 3. End of Quarter 3 (June 30th) 4. End of year (Sept 30th) 5. Endline Survey 6. Ongoing | G11: 1. Consultant 2.1. Project Manager 2.2. Project Ext officer 2.3. Field officer 2.4. Household record keeper | H11: Are men and women to accumulating assets? If not, why? Howare the assets being used for generating better livelihoods? What are the key assets a household should have to promote resilient livelihoods? | I11: 1. United Nations High Commission for Refugees (UNHCR) 2. Office of the Prime Minister (OPM) 3. Lamwo & Kyegegwa District Local Governments. 4. LWR Country Office & HQ. | J11: Quarterly LWR progress reports.
A12: Indicator 1.C: 800 refugees and host community members increase their savings by atleast 50% | B12: % increase calculation: ((new period savings value - prior period savings value)/prior period savings value))*100 ITT Calculation: Count all refugees and host community members who increased their savings by 50% + during the project period. Disaggregated by savings held by men and women within the household. | C12: Unit (s): Men and Women (in HH with savings) Household | D12: Baseline: 1. Household survey Monitoring: 2. Census Endline: 3. Household survey | E12: 1. Consultant database/Endline Report 2.1. ITT 2.2. Consolidated savings group records 2.3. Savings group records | F12: 1. Beginning of year 2 (Oct. 31, 2018) 2. End of qourter 1 (31st December) 2. End of Quarter 2 (March 31st) 3. End of Quarter 3 (June 30th) 4. End of year (Sept 30th) 5. Endline Survey 6. Ongoing | G12: 1. Consultant 2.1. Project Director 2.2. Data entry officer 2.3. Field officer 2.4. Savings group record keeper | H12: Are men and women's savings rate different? If so, why? How much of the household savings is being used for livelihood activities? What is the minimum rate of savings that creates a robust livelihood? | I12: 1. United Nations High Commission for Refugees (UNHCR) 2. Office of the Prime Minister (OPM) 3. Lamwo & Kyegegwa District Local Governments. 4. LWR Country Office & HQ. | J12: Quarterly LWR progress reports.
A13: OUTPUT 1.1: Targeted Refugees and their host communities have access to communty extension services
A14: Indicator 1.1.a: 10 training modules (agronomy, PHH and eco-system mgt) conducted for lead/modal farmers | B14: Lead/Model Farmer - A refugee or host farmer is a member of the refugee/host farmer group selected by group as their peer leader/trainer. Farmer-to-Farmer Extension services - Refers to knowledge & skills provided by the lead/model farmers to at group level or household level during monitoring visit. ITT Calculation: Count the number of lead farmers who receieved atleast 10 training modules in Agronomy, PHH and eco-system management. | C14: Lead Farmers | D14: Baseline: 1. Household survey Monitoring: 2. Census Endline: 3. Household survey | E14: 1. Consultant database/Endline Report 2.1. ITT 2.2. Consolidated savings group records 2.3. Savings group records | F14: 1. Beginning of year 2 (Oct. 31, 2018) 2. End of qourter 1 (31st December) 2. End of Quarter 2 (March 31st) 3. End of Quarter 3 (June 30th) 4. End of year (Sept 30th) 5. Endline Survey 6. Ongoing | G14: 1. Consultant 2.1. Project Director 2.2. Data entry officer 2.3. Field officer | H14: Disaggregate by gender (women & men) | I14: 1. United Nations High Commission for Refugees (UNHCR) 2. Office of the Prime Minister (OPM) 3. Lamwo & Kyegegwa District Local Governments. 4. LWR Country Office & HQ. | J14: Quarterly LWR progress reports.
A15: Indicator 1.1.b: 1600 refugees & host communities receive extension services from lead/model farmers. | B15: Refugee = South Sudanese nationals who have been forced to leave their country to seek asylum in Uganda(Palabek refugee settlement) Host communities = Ugandan nationals living in and around Palabek refugee settlement. ITT Calculation Count the number of refugee and host community farmers who recieved advice/knowledge/skills from the lead farmers. | C15: Refugee and host community farmers | D15: Baseline: 1. Household survey Monitoring: 2. Census/ongoing Endline: 3. Household survey | E15: 1. Consultant database/Endline Report 2.1. ITT 2.2. Consolidated savings group records 2.3. Savings group records | F15: 1. Beginning of year 2 (Oct. 31, 2018) 2. End of qourter 1 (31st December) 2. End of Quarter 2 (March 31st) 3. End of Quarter 3 (June 30th) 4. End of year (Sept 30th) 5. Endline Survey 6. Ongoing | G15: 1. Consultant 2.1. Project Director 2.2. Data entry officer 2.3. Field officer 2.4. Savings group record keeper | H15: Disaggregate by gender (women & men) | I15: 1. United Nations High Commission for Refugees (UNHCR) 2. Office of the Prime Minister (OPM) 3. Lamwo & Kyegegwa District Local Governments. 4. LWR Country Office & HQ. | J15: Quarterly LWR progress reports.
A16: OUTPUT 1.2: Targeted refugees and host community members have access to improved high yielding seeds.
A17: Indicator 1.2.a: 1200 refugees and host community HHs receive high yeilding seeds | B17: Agricultural seeds = high yielding varieties of OSLP, cassava, okra, spinanch, onion, egg plant, and amaranth Host communities = Ugandan nationals living in and around Palabek refugee settlement. ITT Calculation: Count the number of refugees and Host communities who receive the one of the the following seeds: cassava, okra, OSP. | C17: Households | D17: Baseline: 1. Household survey Monitoring: 2. Census/ongoing Endline: 3. Household survey | E17: 1. Consultant database/Endline Report 2.1. ITT 2.2. Consolidated savings group records 2.3. Savings group records | F17: 1. Beginning of year 2 (Oct. 31, 2018) 2. End of qourter 1 (31st December) 2. End of Quarter 2 (March 31st) 3. End of Quarter 3 (June 30th) 4. End of year (Sept 30th) 5. Endline Survey 6. Ongoing | G17: 1. Consultant 2.1. Project Director 2.2. Data entry officer 2.3. Field officer | H17: Disaggregate by gender (women & men) | I17: 1. United Nations High Commission for Refugees (UNHCR) 2. Office of the Prime Minister (OPM) 3. Lamwo & Kyegegwa District Local Governments. 4. LWR Country Office & HQ. | J17: Quarterly LWR progress reports.
A18: OUTPUT 1.3: Targeted refugees engage in off-farm income generating activities.
A19: Indicator 1.3. a. 200 refugees supported to establish small scale businesses. | B19: Small-scale business - a business that has low capital investments and does not have a high volume of sales. ITT Calculation: Count the number of refugees who acquired a loan from the VSLA cash grants provided by LWR. | C19: Men and women operating businesses | D19: Baseline: 1. Household survey Monitoring: 2. Census/ ongoing Endline: 3. Household survey | E19: 1. Consultant database/Endline Report 2.1. ITT 2.2. Consolidated group production records 2.3. Business records | F19: 1. Beginning of year 2 (Oct. 31, 2018) 2. End of qourter 1 (31st December) 2. End of Quarter 2 (March 31st) 3. End of Quarter 3 (June 30th) 4. End of year (Sept 30th) 5. Endline Survey 6. Ongoing | G19: 1. Consultant 2.1. Project Manager 2.2. Project Ext officer 2.3. Field officer 2.4. Household record keeper | H19: Disaggregate by gender (women & men) | I19: 1. United Nations High Commission for Refugees (UNHCR) 2. Office of the Prime Minister (OPM) 3. Lamwo & Kyegegwa District Local Governments. 4. LWR Country Office & HQ. | J19: Quarterly LWR progress reports.
A20: Indicator 1.3.b. 50 refugee and host communities generating income from honey production and Marketing. | B20: Honey = A product of bees got from bee hives. Honey Production: Process of getting honey from bee hives. Honey Marketing: A process of selling honey. ITT Calculation: Count the number of refugee and host community members producing and selling honey. | C20: Men and women engaged in honey production and selling. | D20: Baseline: 1. Household survey Monitoring: 2. Census/ongoing Endline: 3. Household survey | E20: 1. Consultant database/Endline Report 2.1. ITT 2.2. Consolidated group production records 2.3. Household group records | F20: 1. Beginning of year 2 (Oct. 31, 2018) 2. End of qourter 1 (31st December) 2. End of Quarter 2 (March 31st) 3. End of Quarter 3 (June 30th) 4. End of year (Sept 30th) 5. Endline Survey 6. Ongoing | G20: 1. Consultant 2.1. Project Manager 2.2. Project Ext officer 2.3. Field officer 2.4. Group record keeper | H20: Disaggregate by gender (women & men) | I20: 1. United Nations High Commission for Refugees (UNHCR) 2. Office of the Prime Minister (OPM) 3. Lamwo & Kyegegwa District Local Governments. 4. LWR Country Office & HQ. | J20: Quarterly LWR progress reports.
A21: OUTPUT 1.4: Targeted refugees and host community members in engage in VSLA.
A22: Indicator 1.4.a: 30 Village Savings and Lending Associations (groups) formed and strengthened | B22: ITT Calculation: Count number of farmer gropus involved in VSLA. Savings and Credit Group/Cooperative: Regulating fund mobilization at the community level Formed: created Strengthened: trained on purpose, norms | C22: Unit: Number of Saving and Credits groups | D22: Ongoing monitoring; Cooperative/self-help group meetings Partner responsible for Baseline data | E22: 1. ITT 2. Project Coordinator database 3. Social Mobilizer report | F22: 1. Beginning of year 2 (Oct. 31, 2018) 2. End of qourter 1 (31st December) 2. End of Quarter 2 (March 31st) 3. End of Quarter 3 (June 30th) 4. End of year (Sept 30th) 5. Endline Survey 6. Ongoing | G22: 1. Program Manager 2. Project Coordinator 3. Project Officer | H22: Is the number of groups increasing over time? Are the groups getting stronger and/or improving their ability to provide service? | I22: Partners | J22: Quarterly
A23: Indicator 1.4 b. 600 refugee and host community members engaged in VSLA activities (saving and borrowing). | B23: ITT Calculation: Count number of refugees and host communities involved in saving money into the VSLA and involved in taking loans from the group. Savings: Individual VSLA group member takes a stipulated amount of money to VSLA group for keeping/using on his behalf for a stipulated amount of time. Borrowing: Involves a member taking a loan from the VSLA group with a purpose of using the money and later returning it with interest. | C23: Unit: people (men and women) | D23: Baseline: 1. Household survey Monitoring: 2. Census/ongoing Endline: 3. Household survey | E23: 1. Consultant database/Endline Report 2.1. ITT 2.2. Consolidated savings group records 2.3. Savings group records & members pass books | F23: 1. Beginning of year 2 (Oct. 31, 2018) 2. End of qourter 1 (31st December) 2. End of Quarter 2 (March 31st) 3. End of Quarter 3 (June 30th) 4. End of year (Sept 30th) 5. Endline Survey 6. Ongoing | G23: 1. Consultant 2.1. Project Director 2.2. Data entry officer 2.3. Field officer | H23: Disaggregate by gender (women & men) | I23: 1. United Nations High Commission for Refugees (UNHCR) 2. Office of the Prime Minister (OPM) 3. Lamwo & Kyegegwa District Local Governments. 4. LWR Country Office & HQ. | J23: Quarterly LWR progress reports.
A24: Output 1.5: Targeted refugees and host community members engage in eco-system activities that enhance agriculture productivity.
A25: Indicator 1.5.a: 1000 refugee and host community members who established woodlots. | B25: Woodlots: Number of trees planted. ITT Calculation: Count the number of refugees and host communities who planted trees provided by the project. Endline: 3. Household survey | C25: Refugee and host community farmers | D25: Baseline: 1. Household survey Monitoring: 2. Census/ongoing Endline: 3. Household survey | E25: 1. Consultant database/Endline Report 2.1. ITT 2.2. Group records | F25: 1. Beginning of year 2 (Oct. 31, 2018) 2. End of qourter 1 (31st December) 2. End of Quarter 2 (March 31st) 3. End of Quarter 3 (June 30th) 4. End of year (Sept 30th) 5. Endline Survey 6. Ongoing | G25: 1. Consultant 2.1. Project Director 2.2. Data entry officer 2.3. Field officer | H25: Disaggregate by gender (women & men) | I25: 1. United Nations High Commission for Refugees (UNHCR) 2. Office of the Prime Minister (OPM) 3. Lamwo & Kyegegwa District Local Governments. 4. LWR Country Office & HQ. | J25: Quarterly LWR progress reports.
A26: Indicator 1.5.b: 1000 of refugee and host community members who adopt use of organic manure and pesticides. | B26: Organic Manure: Fermented/rotten waste materials prepared by farmers from natural plant materials and animal wastes. Organic Pesticide: Fermented liquid made from natural plant materials, herbs and pepper. ITT Calculation: Count number of refugee and host community members who adopt use of organic manure and pesticides. | C26: Refugee and host community farmers | D26: Baseline: 1. Household survey Monitoring: 2. Census/ongoing Endline: 3. Household survey | E26: 1. Consultant database/Endline Report 2.1. ITT 2.2. Consolidated savings group records 2.3. Savings group records | F26: 1. Beginning of year 2 (Oct. 31, 2018) 2. End of qourter 1 (31st December) 2. End of Quarter 2 (March 31st) 3. End of Quarter 3 (June 30th) 4. End of year (Sept 30th) 5. Endline Survey 6. Ongoing | G26: 1. Consultant 2.1. Project Director 2.2. Data entry officer 2.3. Field officer | H26: Disaggregate by gender (women & men) | I26: 1. United Nations High Commission for Refugees (UNHCR) 2. Office of the Prime Minister (OPM) 3. Lamwo & Kyegegwa District Local Governments. 4. LWR Country Office & HQ. | J26: Quarterly LWR progress reports.
A28: OUTCOME 2: Increased community action towards reduction of SGBV risks, promotion of protection, safety, dignity and fundamental human rights of vulnerable refugees and host communities.
A29: Indicator 2.A: 1000 refugees and host community members taking positive actions towards reduction of protection and SGBV risks as well as promotion of fundamental human rights of vulnerable refugees and host communities. | B29: Positive Actions include: Creating awarenss, advocacy, identifying risks, human rights violations and reporting geared towards prevention & response to SGBV and protection concerns of vulnerable persons in the community. Protection & SGBV Risks include: Sexual assualt, sexual harrasment, Rape, Defilement, Domestic violence, Child marriage, Child sacrifice, Child labour, Human traficking and forced marriage. Fundalmental human rights include: the right to life with dignity, the right to receive humanitarian assistance and the right to protection and security. ITT Calculation: Count the number of community members who took atleast one positive action towards reduction of protection and SGBV risks as well as promotion of fundamental human rights of vulnerable refugees and host communities. | C29: Men, Women, boys and girls. | D29: Baseline: 1. Household survey Monitoring: 2. Census/ongoing Endline: 3. Household survey | E29: 1. Consultant database/Endline Report 2.1. ITT 2.2. Consolidated savings group records 2.3. Savings group records | F29: 1. Beginning of year 2 (Oct. 31, 2018) 2. End of qourter 1 (31st December) 2. End of Quarter 2 (March 31st) 3. End of Quarter 3 (June 30th) 4. End of year (Sept 30th) 5. Endline Survey 6. Ongoing | G29: 1. Consultant 2.1. Project Director 2.2. Data entry officer 2.3. Field officer | H29: Are men and women's involvement in taking action towards reduction of protection and SGBV risks as well as promotion of fundamental human rights of vulnerable refugees and host communities, the same? If not why? If not what actions must be taken to ensure that both men and women are equally involved? How are the local leaders involved? | I29: 1. United Nations High Commission for Refugees (UNHCR) 2. Office of the Prime Minister (OPM) 3. Lamwo & Kyegegwa District Local Governments. 4. LWR Country Office & HQ. | J29: Quarterly LWR progress reports.
A30: OUTPUT 2.1: Protection of all refugees are strengthened through meaningful engagement with communities, with particular attention to at-risk group
A31: Indicator 2.1.a. 820 of women in leadership structures and community groups for community self-management and empowerment | B31: Leadership Structures: Include RWCs, Protection Committees, etc. Community groups include livelihood groups and women groups/women own fora. ITT Calculation: 1. Count the number of women in leadership structures 2. Count the number of women in community groups 3. Add the numbers in 1 & 2. | C31: women | D31: Baseline: 1. Household survey Monitoring: 2. Census/ongoing Endline: 3. Household survey | E31: 1. Consultant database/Endline Report 2.1. ITT 2.2. Consolidated savings group records 2.3. Savings group records | F31: 1. Beginning of year 2 (Oct. 31, 2018) 2. End of qourter 1 (31st December) 2. End of Quarter 2 (March 31st) 3. End of Quarter 3 (June 30th) 4. End of year (Sept 30th) 5. Endline Survey Report 6. Ongoing | G31: 1. Consultant 2.1. Project Director 2.2. Data entry officer 2.3. Field officer | H31: Disaggregate by gender (women & men) | I31: 1. United Nations High Commission for Refugees (UNHCR) 2. Office of the Prime Minister (OPM) 3. Lamwo & Kyegegwa District Local Governments. 4. LWR Country Office & HQ. | J31: Quarterly LWR progress reports.
A32: Indicator 2.1.b. 2000 of complaints addressed through effective feedback mechanisms | B32: Complaits: Any issue of concern to the refugee or host community member that needs to be addressed. Feedback Mechanism: Refers to the complaits desks, and Protection committees. ITT Calculation Count all received and addressed complaits that have been documented in complaits records at the complaits desks. | C32: Complaits | D32: Baseline: 1. Household survey Monitoring: 2. Census/ongoing Endline: 3. Household survey | E32: 1. Consultant database/Endline Report 2.1. ITT 2.2. Consolidated savings group records 2.3. Savings group records | F32: 1. Beginning of year 2 (Oct. 31, 2018) 2. End of qourter 1 (31st December) 2. End of Quarter 2 (March 31st) 3. End of Quarter 3 (June 30th) 4. End of year (Sept 30th) 5. Endline Survey Report 6. Ongoing | G32: 1. Consultant 2.1. Project Director 2.2. Data entry officer 2.3. Field officer | H32: Disaggregate by gender (women & men) | I32: 1. United Nations High Commission for Refugees (UNHCR) 2. Office of the Prime Minister (OPM) 3. Lamwo & Kyegegwa District Local Governments. 4. LWR Country Office & HQ. | J32: Quarterly LWR progress reports.
A33: Indicator 2.1.C. 10,000 of persons with specific needs provided with targeted support | B33: Pesrsons with Specific Needs (PSNS): include: People with disability, elderly, child headed households, terminally ill, SGBV survivors, poor pregnant mothers, poor breast feeding mothers, single mothers, school girls. Trageted support: Includes any support that is given to address PSNs specific vulnerability. This support may include provision of RUMPs, Cash grants, clothing, beddings, baby kits, personal care kits, misson quilts, etc. Endline: 3. Household survey | C33: PSNs | D33: Baseline: 1. Household survey Monitoring: 2. Census/ongoing Endline: 3. Household survey | E33: 1. Consultant database/Endline Report 2.1. ITT 2.2. Consolidated savings group records 2.3. Savings group records | F33: 1. Beginning of year 2 (Oct. 31, 2018) 2. End of qourter 1 (31st December) 2. End of Quarter 2 (March 31st) 3. End of Quarter 3 (June 30th) 4. End of year (Sept 30th) 5. Endline Survey Report 6. Ongoing | G33: 1. Consultant 2.1. Project Director 2.2. Data entry officer 2.3. Field officer | H33: Disaggregate by gender (women & men) | I33: 1. United Nations High Commission for Refugees (UNHCR) 2. Office of the Prime Minister (OPM) 3. Lamwo & Kyegegwa District Local Governments. 4. LWR Country Office & HQ. | J33: Quarterly LWR progress reports.
A34: OUTPUT 2.2: Social cohesion and Peaceful co-existence among refugees and host communities strengthened
A35: Indicator 2.2.a. 40 incidents of conflict within refugee communities as well as between host communities and refugees documented and reported. | B35: Conflicts: Missunderstandings between two parties. ITT Calculation Count the number of conflicts that have been recorded. | C35: conflicts | D35: Baseline: 1. Household survey Monitoring: 2. Census Endline: 3. Household survey | E35: 1. Consultant database/Endline Report 2.1. ITT 2.2. Consolidated savings group records 2.3. Savings group records | F35: 1. Beginning of year 2 (Oct. 31, 2018) 2. End of qourter 1 (31st December) 2. End of Quarter 2 (March 31st) 3. End of Quarter 3 (June 30th) 4. End of year (Sept 30th) 5. Endline Survey 6. Ongoing | G35: 1. Consultant 2.1. Project Director 2.2. Data entry officer 2.3. Field officer | H35: Disaggregate by gender (women & men) | I35: 1. United Nations High Commission for Refugees (UNHCR) 2. Office of the Prime Minister (OPM) 3. Lamwo & Kyegegwa District Local Governments. 4. LWR Country Office & HQ. | J35: Quarterly LWR progress reports.
A36: Indicator 2.2.b. 24 dialogues conducted to resolve conflicts and promote peaceful co-existence. | B36: Dialogues: Discussion between two parties to resolve pending missunderstandings between the two parties. ITT Calculation Count the number of dialogues that have been conducted based on the reports. | C36: dialogues | D36: Baseline: 1. Household survey Monitoring: 2. Census/ongoing Endline: 3. Household survey | E36: 1. Consultant database/Endline Report 2.1. ITT 2.2. Consolidated savings group records 2.3. Savings group records | F36: 1. Beginning of year 2 (Oct. 31, 2018) 2. End of qourter 1 (31st December) 2. End of Quarter 2 (March 31st) 3. End of Quarter 3 (June 30th) 4. End of year (Sept 30th) 5. Endline Survey Report 6. Ongoing | G36: 1. Consultant 2.1. Project Director 2.2. Data entry officer 2.3. Field officer | H36: Disaggregate by gender (women & men) | I36: 1. United Nations High Commission for Refugees (UNHCR) 2. Office of the Prime Minister (OPM) 3. Lamwo & Kyegegwa District Local Governments. 4. LWR Country Office & HQ. | J36: Quarterly LWR progress reports.
A37: Indicator 2.2.C. 2000 refugees and host community engaged in social cohesion activities. | B37: Social Cohesion Activities: Include community dialogues, sports activities and Music, dance and drama activities. ITT Calculation Count the number of dialogues that have been conducted based on the reports. | C37: Men, Women, boys and girls. | D37: Baseline: 1. Household survey Monitoring: 2. Census/ongoing Endline: 3. Household survey | E37: 1. Consultant database/Endline Report 2.1. ITT 2.2. Consolidated savings group records 2.3. Savings group records | F37: 1. Beginning of year 2 (Oct. 31, 2018) 2. End of qourter 1 (31st December) 2. End of Quarter 2 (March 31st) 3. End of Quarter 3 (June 30th) 4. End of year (Sept 30th) 5. Endline Survey Report 6. Ongoing | G37: 1. Consultant 2.1. Project Director 2.2. Data entry officer 2.3. Field officer | H37: Disaggregate by gender (women & men) | I37: 1. United Nations High Commission for Refugees (UNHCR) 2. Office of the Prime Minister (OPM) 3. Lamwo & Kyegegwa District Local Governments. 4. LWR Country Office & HQ. | J37: Quarterly LWR progress reports.
A38: OUTPUT 2.3: Protection systems and mechanisms SGBV prevention and response strengthened
